Workbook
Name alimentos: Alimentos!$A:$A
Name e: #REF!
Name e: #REF!
Name e: #REF!
Name e: #REF!
Name e: #REF!
Name e: #REF!

Sheet Alimentos
A1: Unidades | B1: R$/Kg MO | E1: % CO | F1: % MS | G1: % MS | H1: % MS | I1: % MS | J1: % MS | K1: % MN | L1: % MN | M1: % MS | N1: % MS | O1: Mcal/kg | P1: % MS | Q1: % MS | R1: % MS | S1: % MS | T1: % MS | U1: % MS | V1: %/h | W1: % MS | X1: % MS | Y1: % MS | Z1: % MS | AA1: % MS | AB1: % MS | AC1: % MS | AD1: % MS | AE1: % MS | AF1: mg/kg | AG1: mg/kg | AH1: mg/kg | AI1: mg/kg | AJ1: mg/kg | AK1: mg/kg | AL1: mg/kg | AM1: UI/kg | AN1: UI/kg | AO1: UI/kg | AP1: mg/kg | AQ1: mg/kg | AR1: mg/kg | AS1: UFC/kg | AT1: Protein A | AU1: Protein B | AV1: Protein C | AW1: Protein digestion rate | AX1: RUP Digest | AY1: CP Digestibility | AZ1: NDF Digestibility | BA1: Fat Digestibility | BB1: Lisyne | BC1: Methionine
A2: Alimentos | B2: Custo | C2: Classificação | D2: Tipo | E2: MS | F2: PB | G2: PDR | H2: PNDR | I2: FDN | J2: eFDN | K2: MN>8 | L2: MN>19 | M2: FDNF | N2: FDA | O2: NEl | P2: NDT | Q2: EE | R2: EE Insat | S2: Cinza | T2: CNF | U2: Amido | V2: kd Amido | W2: Met | X2: Lys | Y2: Ca | Z2: P | AA2: Mg | AB2: K | AC2: S | AD2: Na | AE2: Cl | AF2: Co | AG2: Cu | AH2: Mn | AI2: Zn | AJ2: Se | AK2: I | AL2: Fe | AM2: Vit A | AN2: Vit D3 | AO2: Vit E | AP2: Biotina | AQ2: Monensina | AR2: Cr | AS2: Levedura | AT2: % CP | AU2: % CP | AV2: % CP | AW2: %/h | AX2: % | AY2: % | AZ2: % | BA2: % | BB2: % CP | BC2: % CP
A3: Aveia Branca (grão) | C3: Energético | D3: C | E3: 0.92 | F3: 0.129 | G3: =F3-H3 -> 0.1032 | H3: =F3*0.2 -> 0.0258 | I3: 0.314 | J3: =(I3*K3)+(I3*(1-K3)*0.33) -> 0.10362 | K3: 0 | L3: 0 | M3: =IF(D3="C", 0,I3) -> 0 | N3: 0.165 | O3: =(0.0245*P3*100)-0.12 -> 1.7665 | P3: 0.77 | Q3: 0.058 | R3: =Q3*0.835*(34.8+42+1.8)/100 -> 0.03806598 | S3: 0.033 | T3: =1-(I3+Q3+S3+F3) -> 0.466 | U3: 0.408 | V3: 0.2 | Y3: 0.0011 | Z3: 0.004 | AA3: 0.0016 | AB3: 0.0052 | AC3: 0.0019 | AD3: 0.0003 | AE3: 0 | AF3: 0.06 | AG3: 8 | AH3: 43 | AI3: 41 | AJ3: 0.48 | AT3: 0.652 | AU3: 0.288 | AV3: 0.06 | AW3: 0.174 | AX3: 0.75 | AY3: 1 | AZ3: 0.4 | BA3: 1
A4: Aveia Preta (grão) | C4: Energético | D4: C | E4: 0.92 | F4: 0.129 | G4: =F4-H4 -> 0.1032 | H4: =F4*0.2 -> 0.0258 | I4: 0.314 | J4: =(I4*K4)+(I4*(1-K4)*0.33) -> 0.10362 | K4: 0 | L4: 0 | M4: =IF(D4="C", 0,I4) -> 0 | N4: 0.165 | O4: =(0.0245*P4*100)-0.12 -> 1.7665 | P4: 0.77 | Q4: 0.058 | R4: =Q4*0.835*(34.8+42+1.8)/100 -> 0.03806598 | S4: 0.033 | T4: =1-(I4+Q4+S4+F4) -> 0.466 | U4: 0.408 | V4: 0.2 | Y4: 0.0011 | Z4: 0.004 | AA4: 0.0016 | AB4: 0.0052 | AC4: 0.0019 | AD4: 0.0003 | AE4: 0 | AF4: 0.06 | AG4: 8 | AH4: 43 | AI4: 41 | AJ4: 0.48 | AT4: 0.652 | AU4: 0.288 | AV4: 0.06 | AW4: 0.174 | AX4: 0.75 | AY4: 1 | AZ4: 0.4 | BA4: 1
A5: Cevada Grão Moído Fino | C5: Energético | D5: C | E5: 0.88 | F5: 0.125 | G5: =F5-H5 -> 0.09125 | H5: =F5*0.27 -> 0.03375 | I5: 0.22 | J5: =(I5*K5)+(I5*(1-K5)*0.33) -> 0.0726 | M5: =IF(D5="C", 0,I5) -> 0 | N5: 0.078 | O5: =(0.0245*P5*100)-0.12 -> 1.938 | P5: 0.84 | Q5: 0.026 | R5: =Q5*0.761*(0+13.5+55.9+4.3)/100 -> 0.014582282 | S5: 0.029 | T5: =1-(I5+Q5+S5+F5) -> 0.6 | U5: 0.523 | V5: 0.35 | Y5: 0.0006 | Z5: 0.0039 | AA5: 0.0014 | AB5: 0.0056 | AC5: 0.0012 | AD5: 0.0002 | AE5: 0.0013 | AF5: 0.35 | AG5: 6 | AH5: 22 | AI5: 38 | AJ5: 0.11 | AT5: 0.302 | AU5: 0.612 | AV5: 0.086 | AW5: 0.227 | AX5: 0.85 | AY5: 1 | AZ5: 0.48 | BA5: 1
A6: Farelo de Arroz | C6: Energético | D6: C | E6: 0.91 | F6: 0.14 | G6: =F6-H6 -> 0.105 | H6: =F6*0.25 -> 0.035 | I6: 0.301 | J6: =(I6*K6)+(I6*(1-K6)*0.33) -> 0.09933 | M6: =IF(D6="C", 0,I6) -> 0 | N6: 0.173 | O6: =(0.0245*P6*100)-0.12 -> 1.595 | P6: 0.7 | Q6: 0.141 | R6: =Q6*0.85*(39.1+38.1+1.5)/100 -> 0.09432195 | S6: 0.104 | T6: =1-(I6+Q6+S6+F6) -> 0.314 | U6: 0.249 | V6: 0.4 | Y6: 0.0007 | Z6: 0.0178 | AA6: 0.0081 | AB6: 0.0157 | AC6: 0.0019 | AD6: 0.0003 | AE6: 0.0009 | AG6: 10 | AH6: 186 | AI6: 71 | AJ6: 0.17 | AT6: 0.326 | AU6: 0.49 | AV6: 0.184 | AW6: 0.05 | AX6: 0.65 | AY6: 1 | AZ6: 0.33 | BA6: 1
A7: Melaço de Cana | C7: Energético | D7: C | E7: 0.73 | F7: 0.058 | G7: =F7-H7 -> 0.058 | J7: =(I7*K7)+(I7*(1-K7)*0.33) -> 0 | M7: =IF(D7="C", 0,I7) -> 0 | O7: =(0.0245*P7*100)-0.12 -> 1.644 | P7: 0.72 | Q7: 0.01 | R7: =Q7*0.615*(13+54.9+7.5)/100 -> 0.0046371 | S7: 0.133 | T7: =1-(I7+Q7+S7+F7) -> 0.799 | Y7: 0.01 | Z7: 0.001 | AA7: 0.0042 | AB7: 0.0401 | AC7: 0.0047 | AD7: 0.0022 | AE7: 0 | AG7: 66 | AH7: 59 | AI7: 21
A8: Milho com Palha e Sabugo | C8: Energético | D8: C | E8: 0.89 | F8: 0.089 | G8: =F8-H8 -> 0.04895 | H8: =F8*0.45 -> 0.04005 | I8: 0.19 | J8: =(I8*K8)+(I8*(1-K8)*0.33) -> 0.0627 | M8: =IF(D8="C", 0,I8) -> 0 | N8: 0.083 | O8: =(0.0245*P8*100)-0.12 -> 1.791 | P8: 0.78 | Q8: 0.039 | R8: =Q8*0.743*(26+55.1+1.6)/100 -> 0.023963979 | S8: 0.019 | T8: =1-(I8+Q8+S8+F8) -> 0.663 | U8: 0.585 | V8: 0.12 | Y8: 0.0005 | Z8: 0.0028 | AA8: 0.0012 | AB8: 0.0048 | AC8: 0.0009 | AD8: 0.0001 | AE8: 0.0007 | AG8: 3 | AH8: 9 | AI8: 22 | AJ8: 0.07
A9: Milho Floculado | C9: Energético | D9: C | E9: 0.86 | F9: 0.0852 | G9: =F9-H9 -> 0.03408 | H9: =F9*0.6 -> 0.05112 | I9: 0.09 | J9: =(I9*K9)+(I9*(1-K9)*0.33) -> 0.0297 | M9: =IF(D9="C", 0,I9) -> 0 | N9: 0.037 | O9: =(0.0245*P9*100)-0.12 -> 2.036 | P9: 0.88 | Q9: 0.0367 | R9: =Q9*0.929*(23.2+58.4+1.8)/100 -> 0.028434646 | S9: 0.015 | T9: =1-(I9+Q9+S9+F9) -> 0.7731 | U9: 0.756 | V9: 0.35 | Y9: 0.0004 | Z9: 0.003 | AA9: 0.0012 | AB9: 0.0042 | AC9: 0.001 | AD9: 0.0002 | AE9: 0.0008 | AG9: 3 | AH9: 11 | AI9: 27 | AJ9: 0.07 | AT9: 0.239 | AU9: 0.725 | AV9: 0.036 | AW9: 0.049 | AX9: 0.7 | AY9: 1 | AZ9: 0.51 | BA9: 1
A10: Milho Moido Fino | C10: Energético | D10: C | E10: 0.88 | F10: 0.09 | G10: =F10-H10 -> 0.045 | H10: =F10*0.5 -> 0.045 | I10: 0.09 | J10: =(I10*K10)+(I10*(1-K10)*0.33) -> 0.0297 | M10: =IF(D10="C", 0,I10) -> 0 | N10: 0.036 | O10: =(0.0245*P10*100)-0.12 -> 1.9625 | P10: 0.85 | Q10: 0.04 | R10: =Q10*0.952*(24.1+55.7+1.6)/100 -> 0.03099712 | S10: 0.015 | T10: =1-(I10+Q10+S10+F10) -> 0.765 | U10: 0.748 | V10: 0.15 | Y10: 0.0004 | Z10: 0.003 | AA10: 0.0012 | AB10: 0.0042 | AC10: 0.001 | AD10: 0.0002 | AE10: 0.0008 | AG10: 3 | AH10: 11 | AI10: 27 | AJ10: 0.07 | AT10: 0.239 | AU10: 0.725 | AV10: 0.036 | AW10: 0.049 | AX10: 0.7 | AY10: 1 | AZ10: 0.51 | BA10: 1
A11: Milho Moido Grosso | C11: Energético | D11: C | E11: 0.88 | F11: 0.09 | G11: =F11-H11 -> 0.036 | H11: =F11*0.6 -> 0.054 | I11: 0.09 | J11: =(I11*K11)+(I11*(1-K11)*0.33) -> 0.0297 | M11: =IF(D11="C", 0,I11) -> 0 | N11: 0.036 | O11: =(0.0245*P11*100)-0.12 -> 1.84 | P11: 0.8 | Q11: 0.04 | R11: =Q11*0.952*(24.1+55.7+1.6)/100 -> 0.03099712 | S11: 0.015 | T11: =1-(I11+Q11+S11+F11) -> 0.765 | U11: 0.748 | V11: 0.12 | Y11: 0.0004 | Z11: 0.003 | AA11: 0.0012 | AB11: 0.0042 | AC11: 0.001 | AD11: 0.0002 | AE11: 0.0008 | AG11: 3 | AH11: 11 | AI11: 27 | AJ11: 0.07 | AT11: 0.239 | AU11: 0.725 | AV11: 0.036 | AW11: 0.049 | AX11: 0.7 | AY11: 1 | AZ11: 0.51 | BA11: 1
A12: Milho Umido | C12: Energético | D12: C | E12: 0.68 | F12: 0.092 | G12: =F12-H12 -> 0.0506 | H12: =F12*0.45 -> 0.0414 | I12: 0.108 | J12: =(I12*K12)+(I12*(1-K12)*0.33) -> 0.03564 | M12: =IF(D12="C", 0,I12) -> 0 | N12: 0.041 | O12: =(0.0245*P12*100)-0.12 -> 2.036 | P12: 0.88 | Q12: 0.039 | R12: =Q12*0.743*(26+55.1+1.6)/100 -> 0.023963979 | S12: 0.015 | T12: =1-(I12+Q12+S12+F12) -> 0.746 | U12: 0.707 | V12: 0.29 | Y12: 0.0003 | Z12: 0.003 | AA12: 0.0012 | AB12: 0.0043 | AC12: 0.001 | AD12: 0.0001 | AE12: 0.0005 | AG12: 1 | AH12: 7 | AI12: 21 | AJ12: 0.07 | AT12: 0.279 | AU12: 0.714 | AV12: 0.007 | AW12: 0.051 | AX12: 0.9 | AY12: 1 | AZ12: 0.51 | BA12: 1
A13: Milho Umido Ensilado, 68 MS Fino | C13: Energético | D13: C | E13: 0.65 | F13: 0.092 | G13: =F13-H13 -> 0.0506 | H13: =F13*0.45 -> 0.0414 | I13: 0.108 | J13: =(I13*K13)+(I13*(1-K13)*0.33) -> 0.03564 | M13: =IF(D13="C", 0,I13) -> 0 | N13: 0.041 | O13: =(0.0245*P13*100)-0.12 -> 2.0605 | P13: 0.89 | Q13: 0.039 | R13: =Q13*0.743*(26+55.1+1.6)/100 -> 0.023963979 | S13: 0.015 | T13: =1-(I13+Q13+S13+F13) -> 0.746 | U13: 0.707 | V13: 0.37 | Y13: 0.0003 | Z13: 0.003 | AA13: 0.0012 | AB13: 0.0043 | AC13: 0.001 | AD13: 0.0001 | AE13: 0.0005 | AG13: 1 | AH13: 7 | AI13: 21 | AJ13: 0.07 | AT13: 0.279 | AU13: 0.714 | AV13: 0.007 | AW13: 0.051 | AX13: 0.9 | AY13: 1 | AZ13: 0.51 | BA13: 1
A14: Milho Umido Ensilado, 68 MS Grosso | C14: Energético | D14: C | E14: 0.68 | F14: 0.092 | G14: =F14-H14 -> 0.0506 | H14: =F14*0.45 -> 0.0414 | I14: 0.108 | J14: =(I14*K14)+(I14*(1-K14)*0.33) -> 0.03564 | M14: =IF(D14="C", 0,I14) -> 0 | N14: 0.041 | O14: =(0.0245*P14*100)-0.12 -> 2.036 | P14: 0.88 | Q14: 0.039 | R14: =Q14*0.743*(26+55.1+1.6)/100 -> 0.023963979 | S14: 0.015 | T14: =1-(I14+Q14+S14+F14) -> 0.746 | U14: 0.707 | V14: 0.29 | Y14: 0.0003 | Z14: 0.003 | AA14: 0.0012 | AB14: 0.0043 | AC14: 0.001 | AD14: 0.0001 | AE14: 0.0005 | AG14: 1 | AH14: 7 | AI14: 21 | AJ14: 0.07 | AT14: 0.279 | AU14: 0.714 | AV14: 0.007 | AW14: 0.051 | AX14: 0.9 | AY14: 1 | AZ14: 0.51 | BA14: 1
A15: Milho Umido Ensilado, 78 MS Fino | C15: Energético | D15: C | E15: 0.78 | F15: 0.09 | G15: =F15-H15 -> 0.0495 | H15: =F15*0.45 -> 0.0405 | I15: 0.103 | J15: =(I15*K15)+(I15*(1-K15)*0.33) -> 0.03399 | M15: =IF(D15="C", 0,I15) -> 0 | N15: 0.039 | O15: =(0.0245*P15*100)-0.12 -> 2.0115 | P15: 0.87 | Q15: 0.038 | R15: =Q15*0.743*(26+55.1+1.6)/100 -> 0.023349518 | S15: 0.015 | T15: =1-(I15+Q15+S15+F15) -> 0.754 | U15: 0.722 | V15: 0.27 | Y15: 0.0003 | Z15: 0.003 | AA15: 0.0012 | AB15: 0.0043 | AC15: 0.001 | AD15: 0.0001 | AE15: 0.0005 | AG15: 1 | AH15: 7 | AI15: 21 | AJ15: 0.07 | AT15: 0.279 | AU15: 0.714 | AV15: 0.007 | AW15: 0.051 | AX15: 0.9 | AY15: 1 | AZ15: 0.51 | BA15: 1
A16: Milho Umido Ensilado, 78 MS Grosso | C16: Energético | D16: C | E16: 0.78 | F16: 0.092 | G16: =F16-H16 -> 0.0506 | H16: =F16*0.45 -> 0.0414 | I16: 0.103 | J16: =(I16*K16)+(I16*(1-K16)*0.33) -> 0.03399 | M16: =IF(D16="C", 0,I16) -> 0 | N16: 0.038 | O16: =(0.0245*P16*100)-0.12 -> 1.987 | P16: 0.86 | Q16: 0.038 | R16: =Q16*0.743*(26+55.1+1.6)/100 -> 0.023349518 | S16: 0.015 | T16: =1-(I16+Q16+S16+F16) -> 0.752 | U16: 0.722 | V16: 0.17 | Y16: 0.0003 | Z16: 0.003 | AA16: 0.0012 | AB16: 0.0043 | AC16: 0.001 | AD16: 0.0001 | AE16: 0.0005 | AG16: 1 | AH16: 7 | AI16: 21 | AJ16: 0.07 | AT16: 0.279 | AU16: 0.714 | AV16: 0.007 | AW16: 0.051 | AX16: 0.9 | AY16: 1 | AZ16: 0.51 | BA16: 1
A17: Sorgo Floculado | C17: Energético | D17: C | E17: 0.89 | F17: 0.113 | G17: =F17-H17 -> 0.05989 | H17: =F17*0.47 -> 0.05311 | I17: 0.174 | J17: =(I17*K17)+(I17*(1-K17)*0.33) -> 0.05742 | M17: =IF(D17="C", 0,I17) -> 0 | N17: 0.06 | O17: =(0.0245*P17*100)-0.12 -> 1.9625 | P17: 0.85 | Q17: 0.036 | R17: =Q17*0.811*(29.7+48.2+1.6)/100 -> 0.02321082 | S17: 0.02 | T17: =1-(I17+Q17+S17+F17) -> 0.657 | U17: 0.598 | V17: 0.3 | Y17: 0.0007 | Z17: 0.0035 | AA17: 0.0017 | AB17: 0.0047 | AC17: 0.0011 | AD17: 0.0001 | AE17: 0.0006 | AG17: 6 | AH17: 21 | AI17: 25 | AJ17: 0.46 | AT17: 0.189 | AU17: 0.794 | AV17: 0.017 | AW17: 0.055 | AX17: 0.85 | AY17: 1 | AZ17: 0.35 | BA17: 1
A18: Sorgo Grão Moido Fino | C18: Energético | D18: C | E18: 0.89 | F18: 0.113 | G18: =F18-H18 -> 0.05763 | H18: =F18*0.49 -> 0.05537 | I18: 0.174 | J18: =(I18*K18)+(I18*(1-K18)*0.33) -> 0.05742 | M18: =IF(D18="C", 0,I18) -> 0 | N18: 0.06 | O18: =(0.0245*P18*100)-0.12 -> 1.84 | P18: 0.8 | Q18: 0.036 | R18: =Q18*0.811*(29.7+48.2+1.6)/100 -> 0.02321082 | S18: 0.02 | T18: =1-(I18+Q18+S18+F18) -> 0.657 | U18: 0.598 | V18: 0.15 | Y18: 0.0007 | Z18: 0.0035 | AA18: 0.0017 | AB18: 0.0047 | AC18: 0.0011 | AD18: 0.0001 | AE18: 0.0006 | AG18: 6 | AH18: 21 | AI18: 25 | AJ18: 0.46 | AT18: 0.189 | AU18: 0.794 | AV18: 0.017 | AW18: 0.055 | AX18: 0.85 | AY18: 1 | AZ18: 0.35 | BA18: 1
A19: Sorgo Grão Umido Ensilado | C19: Energético | D19: C | E19: 0.78 | F19: 0.113 | G19: =F19-H19 -> 0.06215 | H19: =F19*0.45 -> 0.05085 | I19: 0.23 | J19: =(I19*K19)+(I19*(1-K19)*0.33) -> 0.0759 | M19: =IF(D19="C", 0,I19) -> 0 | N19: 0.06 | O19: =(0.0245*P19*100)-0.12 -> 1.9625 | P19: 0.85 | Q19: 0.036 | R19: =Q19*0.811*(29.7+48.2+1.6)/100 -> 0.02321082 | S19: 0.02 | T19: =1-(I19+Q19+S19+F19) -> 0.601 | U19: 0.545 | V19: 0.2 | Y19: 0.0007 | Z19: 0.0035 | AA19: 0.0017 | AB19: 0.0047 | AC19: 0.0011 | AD19: 0.0001 | AE19: 0.0006 | AG19: 6 | AH19: 21 | AI19: 25 | AJ19: 0.46 | AT19: 0.189 | AU19: 0.794 | AV19: 0.017 | AW19: 0.055 | AX19: 0.85 | AY19: 1 | AZ19: 0.35 | BA19: 1
A20: Trigo Grão | C20: Energético | D20: C | E20: 0.89 | F20: 0.142 | G20: =F20-H20 -> 0.1136 | H20: =F20*0.2 -> 0.0284 | I20: 0.117 | J20: =(I20*K20)+(I20*(1-K20)*0.33) -> 0.03861 | M20: =IF(D20="C", 0,I20) -> 0 | N20: 0.052 | O20: =(0.0245*P20*100)-0.12 -> 2.036 | P20: 0.88 | Q20: 0.02 | R20: =Q20*0.905*(14.7+60.2+4.3)/100 -> 0.0143352 | S20: 0.02 | T20: =1-(I20+Q20+S20+F20) -> 0.701 | U20: 0.655 | V20: 0.4 | Y20: 0.0005 | Z20: 0.0043 | AA20: 0.0015 | AB20: 0.005 | AC20: 0.0015 | AD20: 0.0001 | AE20: 0.0011 | AG20: 5 | AH20: 42 | AI20: 40 | AJ20: 0.28 | AT20: 0.271 | AU20: 0.651 | AV20: 0.078 | AW20: 0.188 | AX20: 0.95 | AY20: 1 | AZ20: 0.41 | BA20: 1
A21: Alfafa Feno | C21: Forragem | D21: F | E21: 0.9 | F21: 0.17 | G21: =F21-H21 -> 0.1275 | H21: =F21*0.25 -> 0.0425 | I21: 0.46 | J21: =(I21*K21)+(I21*(1-K21)*0.33) -> 0.46 | K21: 1 | L21: 1 | M21: =IF(D21="C", 0,I21) -> 0.46 | N21: 0.363 | O21: =(0.0245*P21*100)-0.12 -> 1.3745 | P21: 0.61 | Q21: 0.025 | R21: =Q21*0.55*(0.4+2.4+18.5+36.8)/100 -> 0.00798875 | S21: 0.11 | T21: =1-(I21+Q21+S21+F21) -> 0.235 | U21: 0.014 | V21: 0.3 | Y21: 0.0147 | Z21: 0.0028 | AA21: 0.0029 | AB21: 0.0237 | AC21: 0.0026 | AD21: 0.001 | AE21: 0.0065 | AF21: 0.31 | AG21: 9 | AH21: 44 | AI21: 28 | AJ21: 0.36 | AK21: 0.16
A22: Alfafa Silagem Pré-Secada | C22: Forragem | D22: F | E22: 0.35 | F22: 0.17 | G22: =F22-H22 -> 0.136 | H22: =F22*0.2 -> 0.034 | I22: 0.46 | J22: =(I22*K22)+(I22*(1-K22)*0.33) -> 0.39836 | K22: 0.8 | L22: 0.5 | M22: =IF(D22="C", 0,I22) -> 0.46 | N22: 0.359 | O22: =(0.0245*P22*100)-0.12 -> 1.3745 | P22: 0.61 | Q22: 0.033 | R22: =Q22*0.513*(2+15.9+38.7)/100 -> 0.009581814 | S22: 0.11 | T22: =1-(I22+Q22+S22+F22) -> 0.227 | U22: 0.014 | V22: 0.3 | Y22: 0.0147 | Z22: 0.0028 | AA22: 0.0029 | AB22: 0.0237 | AC22: 0.0026 | AD22: 0.001 | AE22: 0.0065 | AF22: 0.31 | AG22: 9 | AH22: 44 | AI22: 28 | AJ22: 0.36 | AK22: 0.16
A23: Alfafa Verde Colhida | C23: Forragem | D23: F | E23: 0.25 | F23: 0.17 | G23: =F23-H23 -> 0.1105 | H23: =F23*0.35 -> 0.0595 | I23: 0.43 | J23: =(I23*K23)+(I23*(1-K23)*0.33) -> 0.43 | K23: 1 | L23: 1 | M23: =IF(D23="C", 0,I23) -> 0.43 | N23: 0.314 | O23: =(0.0245*P23*100)-0.12 -> 1.4235 | P23: 0.63 | Q23: 0.025 | R23: =Q23*0.651*(2.3+19+49.7)/100 -> 0.01155525 | S23: 0.11 | T23: =1-(I23+Q23+S23+F23) -> 0.265 | U23: 0.016 | V23: 0.3 | Y23: 0.0147 | Z23: 0.0028 | AA23: 0.0029 | AB23: 0.0237 | AC23: 0.0026 | AD23: 0.001 | AE23: 0.0065 | AF23: 0.31 | AG23: 9 | AH23: 44 | AI23: 28 | AJ23: 0.36 | AK23: 0.16
A24: Bagaço de Cana | C24: Forragem | D24: F | E24: 0.74 | F24: 0.0217 | G24: 0 | H24: 0 | I24: 0.85 | J24: =(I24*K24)+(I24*(1-K24)*0.33) -> 0.85 | K24: 1 | L24: 0 | M24: =IF(D24="C", 0,I24) -> 0.85 | N24: 0.62 | O24: =(0.0245*P24*100)-0.12 -> 0.14999 | P24: 0.1102 | Q24: 0.002 | S24: 0.0161 | T24: =1-(I24+Q24+S24+F24) -> 0.1102 | Y24: 0 | Z24: 0 | AA24: 0 | AB24: 0 | AC24: 0 | AD24: 0 | AE24: 0 | AF24: 0 | AG24: 0 | AH24: 0 | AK24: 0 | AL24: 0
A25: Cana-de-Açúcar | C25: Forragem | D25: F | E25: 0.3 | F25: 0.025 | G25: =F25-H25 -> 0.025 | H25: 0 | I25: 0.5 | J25: =(I25*K25)+(I25*(1-K25)*0.33) -> 0.5 | K25: 1 | L25: 0 | M25: =IF(D25="C", 0,I25) -> 0.5 | N25: 0.36 | O25: =(0.0245*P25*100)-0.12 -> 1.301 | P25: 0.58 | Q25: 0.009 | S25: 0.041 | T25: =1-(I25+Q25+S25+F25) -> 0.425 | U25: 0 | V25: 0 | Y25: 0.0007 | Z25: 0.0005 | AA25: 0.001 | AB25: 0.0206 | AC25: 0.0018 | AD25: 0.0001 | AE25: 0 | AF25: 0 | AG25: 0 | AH25: 0 | AI25: 0 | AJ25: 0
A26: Gramínea Temperada Feno | C26: Forragem | D26: F | E26: 0.91 | F26: 0.147 | G26: =F26-H26 -> 0.11025 | H26: =F26*0.25 -> 0.03675 | I26: 0.57 | J26: =(I26*K26)+(I26*(1-K26)*0.33) -> 0.57 | K26: 1 | L26: 1 | M26: =IF(D26="C", 0,I26) -> 0.57 | N26: 0.364 | O26: =(0.0245*P26*100)-0.12 -> 1.35 | P26: 0.6 | Q26: 0.049 | R26: =Q26*0.24*(5.1+19.1+39.1)/100 -> 0.00744408 | S26: 0.088 | T26: =1-(I26+Q26+S26+F26) -> 0.146 | U26: 0.028 | V26: 0.3 | Y26: 0.0066 | Z26: 0.0029 | AA26: 0.0023 | AB26: 0.0213 | AC26: 0.0024 | AD26: 0.0008 | AE26: 0.0092 | AG26: 9 | AH26: 72 | AI26: 25 | AJ26: 0.06
A27: Gramínea Temperada Silagem Pré-Secada | C27: Forragem | D27: F | E27: 0.3 | F27: 0.18 | G27: =F27-H27 -> 0.144 | H27: =F27*0.2 -> 0.036 | I27: 0.48 | J27: =(I27*K27)+(I27*(1-K27)*0.33) -> 0.41568 | K27: 0.8 | L27: 0.5 | M27: =IF(D27="C", 0,I27) -> 0.48 | N27: 0.311 | O27: =(0.0245*P27*100)-0.12 -> 1.399 | P27: 0.62 | Q27: 0.049 | R27: =Q27*0.24*(5.1+19.1+39.1)/100 -> 0.00744408 | S27: 0.081 | T27: =1-(I27+Q27+S27+F27) -> 0.21 | U27: 0.04 | V27: 0.3 | Y27: 0.0055 | Z27: 0.0029 | AA27: 0.0023 | AB27: 0.0254 | AC27: 0.0021 | AD27: 0.0005 | AE27: 0.0067 | AG27: 9 | AH27: 74 | AI27: 30 | AJ27: 0.09
A28: Gramínea Temperada Verde Colhido | C28: Forragem | D28: F | E28: 0.25 | F28: 0.21 | G28: =F28-H28 -> 0.1365 | H28: =F28*0.35 -> 0.0735 | I28: 0.45 | J28: =(I28*K28)+(I28*(1-K28)*0.33) -> 0.45 | K28: 1 | L28: 1 | M28: =IF(D28="C", 0,I28) -> 0.45 | N28: 0.3 | O28: =(0.0245*P28*100)-0.12 -> 1.448 | P28: 0.64 | Q28: 0.05 | R28: =Q28*0.24*(5.1+19.1+39.1)/100 -> 0.007596 | S28: 0.099 | T28: =1-(I28+Q28+S28+F28) -> 0.191 | U28: 0.04 | V28: 0.3 | Y28: 0.0057 | Z28: 0.0036 | AA28: 0.0022 | AB28: 0.0311 | AC28: 0.0021 | AD28: 0.0005 | AE28: 0.0067 | AG28: 9 | AH28: 56 | AI28: 31
A29: Napier Ensilado | C29: Forragem | D29: F | E29: 0.25 | F29: 0.09 | G29: =F29-H29 -> 0.072 | H29: =F29*0.2 -> 0.018 | I29: 0.7 | J29: =(I29*K29)+(I29*(1-K29)*0.33) -> 0.6531 | K29: 0.9 | L29: 0.1 | M29: =IF(D29="C", 0,I29) -> 0.7 | N29: 0.45 | O29: =(0.0245*P29*100)-0.12 -> 1.2275 | P29: 0.55 | Q29: 0.023 | R29: =Q29*0.462*(3.8+20+44.3)/100 -> 0.007236306 | S29: 0.065 | T29: =1-(I29+Q29+S29+F29) -> 0.122 | U29: 0.02 | V29: 0.2 | Y29: 0.0039 | Z29: 0.0022 | AA29: 0.0015 | AB29: 0.014 | AC29: 0.0038 | AD29: 0.0014 | AE29: 0.0054 | AG29: 8 | AH29: 62 | AI29: 32
A30: Napier Verde Bem Manejado | C30: Forragem | D30: F | E30: 0.22 | F30: 0.14 | G30: =F30-H30 -> 0.098 | H30: =F30*0.3 -> 0.042 | I30: 0.65 | J30: =(I30*K30)+(I30*(1-K30)*0.33) -> 0.497575 | K30: 0.65 | L30: 0.03 | M30: =IF(D30="C", 0,I30) -> 0.65 | N30: 0.42 | O30: =(0.0245*P30*100)-0.12 -> 1.35 | P30: 0.6 | Q30: 0.026 | R30: =Q30*0.462*(3.8+20+44.3)/100 -> 0.008180172 | S30: 0.06 | T30: =1-(I30+Q30+S30+F30) -> 0.124 | U30: 0.024 | V30: 0.2 | Y30: 0.0039 | Z30: 0.0022 | AA30: 0.0015 | AB30: 0.014 | AC30: 0.0038 | AD30: 0.0014 | AE30: 0.0054 | AG30: 8 | AH30: 62 | AI30: 32
A31: Napier Verde Mal Manejado | C31: Forragem | D31: F | E31: 0.3 | F31: 0.05 | G31: =F31-H31 -> 0.05 | H31: 0 | I31: 0.8 | J31: =(I31*K31)+(I31*(1-K31)*0.33) -> 0.6392 | K31: 0.7 | L31: 0.05 | M31: =IF(D31="C", 0,I31) -> 0.8 | N31: 0.51 | O31: =(0.0245*P31*100)-0.12 -> 1.105 | P31: 0.5 | Q31: 0.016 | R31: =Q31*0.462*(3.8+20+44.3)/100 -> 0.005033952 | S31: 0.08 | T31: =1-(I31+Q31+S31+F31) -> 0.054 | U31: 0 | V31: 0 | Y31: 0.002 | Z31: 0.001 | AA31: 0.001 | AB31: 0.009 | AC31: 0.002 | AD31: 0 | AE31: 0 | AG31: 5 | AH31: 50 | AI31: 25
A32: Pastagem Temperada Bem Manejada | C32: Forragem | D32: F | E32: 0.22 | F32: 0.24 | G32: =F32-H32 -> 0.156 | H32: =F32*0.35 -> 0.084 | I32: 0.4 | J32: =(I32*K32)+(I32*(1-K32)*0.33) -> 0.4 | K32: 1 | L32: 1 | M32: =IF(D32="C", 0,I32) -> 0.4 | N32: 0.25 | O32: =(0.0245*P32*100)-0.12 -> 1.4725 | P32: 0.65 | Q32: 0.05 | R32: =Q32*0.24*(5.1+19.1+39.1)/100 -> 0.007596 | S32: 0.098 | T32: =1-(I32+Q32+S32+F32) -> 0.212 | U32: 0.04 | V32: 0.3 | Y32: 0.0056 | Z32: 0.0044 | AA32: 0.002 | AB32: 0.0336 | AC32: 0.002 | AD32: 0.0002 | AE32: 0.0056 | AG32: 10 | AH32: 75 | AI32: 36
A33: Pastagem Azevem | C33: Forragem | D33: F | E33: 0.22 | F33: 0.24 | G33: =F33-H33 -> 0.156 | H33: =F33*0.35 -> 0.084 | I33: 0.4 | J33: =(I33*K33)+(I33*(1-K33)*0.33) -> 0.4 | K33: 1 | L33: 1 | M33: =IF(D33="C", 0,I33) -> 0.4 | N33: 0.25 | O33: =(0.0245*P33*100)-0.12 -> 1.4725 | P33: 0.65 | Q33: 0.05 | R33: =Q33*0.24*(5.1+19.1+39.1)/100 -> 0.007596 | S33: 0.098 | T33: =1-(I33+Q33+S33+F33) -> 0.212 | U33: 0.04 | V33: 0.3 | Y33: 0.0056 | Z33: 0.0044 | AA33: 0.002 | AB33: 0.0336 | AC33: 0.002 | AD33: 0.0002 | AE33: 0.0056 | AG33: 10 | AH33: 75 | AI33: 36
A34: Pastagem Temperada Mal Manejada | C34: Forragem | D34: F | E34: 0.27 | F34: 0.09 | G34: =F34-H34 -> 0.0585 | H34: =F34*0.35 -> 0.0315 | I34: 0.6 | J34: =(I34*K34)+(I34*(1-K34)*0.33) -> 0.6 | K34: 1 | L34: 1 | M34: =IF(D34="C", 0,I34) -> 0.6 | N34: 0.4 | O34: =(0.0245*P34*100)-0.12 -> 1.2275 | P34: 0.55 | Q34: 0.04 | R34: =Q34*0.24*(5.1+19.1+39.1)/100 -> 0.0060768 | S34: 0.07 | T34: =1-(I34+Q34+S34+F34) -> 0.2 | U34: 0.02 | V34: 0.3 | Y34: 0.0047 | Z34: 0.0026 | AA34: 0.0018 | AB34: 0.0197 | AC34: 0.0017 | AD34: 0.0002 | AE34: 0.0066 | AG34: 8 | AH34: 90 | AI34: 25 | AJ34: 0.06
A35: Pastagem Tropical Bem Manejada | C35: Forragem | D35: F | E35: 0.2 | F35: 0.17 | G35: =F35-H35 -> 0.119 | H35: =F35*0.3 -> 0.051 | I35: 0.65 | J35: =(I35*K35)+(I35*(1-K35)*0.33) -> 0.65 | K35: 1 | L35: 1 | M35: =IF(D35="C", 0,I35) -> 0.65 | N35: 0.38 | O35: =(0.0245*P35*100)-0.12 -> 1.399 | P35: 0.62 | Q35: 0.021 | R35: =Q35*0.405*(3.3+18.8+20.8)/100 -> 0.003648645 | S35: 0.065 | T35: =1-(I35+Q35+S35+F35) -> 0.094 | U35: 0.02 | V35: 0.3 | Y35: 0.0039 | Z35: 0.0022 | AA35: 0.0015 | AB35: 0.024 | AC35: 0.0038 | AD35: 0.0014 | AE35: 0.0054 | AG35: 8 | AH35: 62 | AI35: 32
A36: Pastagem Tropical Mal Manejada | C36: Forragem | D36: F | E36: 0.22 | F36: 0.1 | G36: =F36-H36 -> 0.1 | H36: 0 | I36: 0.7 | J36: =(I36*K36)+(I36*(1-K36)*0.33) -> 0.7 | K36: 1 | L36: 1 | M36: =IF(D36="C", 0,I36) -> 0.7 | N36: 0.45 | O36: =(0.0245*P36*100)-0.12 -> 1.301 | P36: 0.58 | Q36: 0.015 | R36: =Q36*0.405*(3.3+18.8+20.8)/100 -> 0.002606175 | S36: 0.09 | T36: =1-(I36+Q36+S36+F36) -> 0.095 | U36: 0 | V36: 0 | Y36: 0.002 | Z36: 0.001 | AA36: 0.001 | AB36: 0.009 | AC36: 0.002 | AD36: 0 | AE36: 0 | AG36: 5 | AH36: 50 | AI36: 25
A37: Silagem de Cana | C37: Forragem | D37: F | E37: 0.28 | F37: 0.03 | G37: =F37-H37 -> 0.03 | H37: 0 | I37: 0.65 | J37: =(I37*K37)+(I37*(1-K37)*0.33) -> 0.410475 | K37: 0.45 | L37: 0.01 | M37: =IF(D37="C", 0,I37) -> 0.65 | N37: 0.415 | O37: =(0.0245*P37*100)-0.12 -> 1.154 | P37: 0.52 | Q37: 0.01 | R37: 0 | S37: 0.05 | T37: =1-(I37+Q37+S37+F37) -> 0.26 | U37: 0 | V37: 0 | Y37: 0.0007 | Z37: 0.0005 | AA37: 0.001 | AB37: 0.0206 | AC37: 0.0018 | AD37: 0.0001 | AE37: 0
A38: Silagem de Milho, 27 MS | C38: Forragem | D38: F | E38: 0.27 | F38: 0.09 | G38: =F38-H38 -> 0.063 | H38: =F38*0.3 -> 0.027 | I38: 0.57 | J38: =(I38*K38)+(I38*(1-K38)*0.33) -> 0.474525 | K38: 0.75 | L38: 0.05 | M38: =IF(D38="C", 0,I38) -> 0.57 | N38: 0.383 | O38: =(0.0245*P38*100)-0.12 -> 1.375235 | P38: 0.6103 | Q38: 0.032 | R38: =Q38*0.695*(19.2+47.7+8.3)/100 -> 0.01672448 | S38: 0.048 | T38: =1-(I38+Q38+S38+F38) -> 0.26 | U38: 0.2 | V38: 0.36 | Y38: 0.0029 | Z38: 0.0024 | AA38: 0.0019 | AB38: 0.013 | AC38: 0.0014 | AD38: 0.0001 | AE38: 0.003 | AG38: 6 | AH38: 46 | AI38: 29 | AJ38: 0.04
A39: Silagem de Milho, 30 MS | C39: Forragem | D39: F | E39: 0.3 | F39: 0.07 | G39: =F39-H39 -> 0.049 | H39: =F39*0.3 -> 0.021 | I39: 0.53 | J39: =(I39*K39)+(I39*(1-K39)*0.33) -> 0.441225 | K39: 0.75 | L39: 0.05 | M39: =IF(D39="C", 0,I39) -> 0.53 | N39: 0.35 | O39: =(0.0245*P39*100)-0.12 -> 1.43183 | P39: 0.6334 | Q39: 0.032 | R39: =Q39*0.695*(19.2+47.7+8.3)/100 -> 0.01672448 | S39: 0.045 | T39: =1-(I39+Q39+S39+F39) -> 0.323 | U39: 0.231 | V39: 0.34 | Y39: 0.0029 | Z39: 0.0024 | AA39: 0.0019 | AB39: 0.013 | AC39: 0.0014 | AD39: 0.0001 | AE39: 0.003 | AG39: 6 | AH39: 46 | AI39: 29 | AJ39: 0.04
A40: Silagem de Milho, 32 MS | C40: Forragem | D40: F | E40: 0.32 | F40: 0.065 | G40: =F40-H40 -> 0.0455 | H40: =F40*0.3 -> 0.0195 | I40: 0.49 | J40: =(I40*K40)+(I40*(1-K40)*0.33) -> 0.407925 | K40: 0.75 | L40: 0.05 | M40: =IF(D40="C", 0,I40) -> 0.49 | N40: 0.297 | O40: =(0.0245*P40*100)-0.12 -> 1.522725 | P40: 0.6705 | Q40: 0.032 | R40: =Q40*0.695*(19.2+47.7+8.3)/100 -> 0.01672448 | S40: 0.043 | T40: =1-(I40+Q40+S40+F40) -> 0.37 | U40: 0.251 | V40: 0.32 | Y40: 0.0028 | Z40: 0.0026 | AA40: 0.0017 | AB40: 0.012 | AC40: 0.0014 | AD40: 0.0001 | AE40: 0.0029 | AG40: 6 | AH40: 36 | AI40: 24 | AJ40: 0.04
...

Sheet Lactação
A1: LACTAÇÃO | B1: ECC ( 1 a 5) | C1: Paridade (0 ou 1) | D1: Peso médio, kg | E1: DEL médio, d | F1: Leite médio, kg/d | G1: Gordura, % | H1: Proteína, % | I1: Lactose, %
A4: Unidades | B4: R$/Kg MN | E4: % CO | F4: % MS | G4: % MS | H4: % MS | I4: % MS | J4: % MS | K4: % MN | L4: % MN | M4: % MS | N4: % MS | O4: Mcal/kg | P4: % MS | Q4: % MS | R4: % MS | S4: % MS | T4: % MS | U4: % MS | V4: %/h | W4: % MS | X4: % MS | Y4: % MS | Z4: % MS | AA4: % MS | AB4: % MS | AC4: % MS | AD4: % MS | AE4: % MS | AF4: mg/kg | AG4: mg/kg | AH4: mg/kg | AI4: mg/kg | AJ4: mg/kg | AK4: mg/kg | AL4: mg/kg | AM4: UI/kg | AN4: UI/kg | AO4: UI/kg | AP4: mg/kg | AQ4: mg/kg | AR4: mg/kg | AS4: UFC/kg
A5: Alimento | B5: Custo | E5: MS | F5: PB | G5: PDR | H5: PNDR | I5: FDN | J5: eFDN | K5: MN>8 | L5: MN>19 | M5: FDNF | N5: FDA | O5: NEl | P5: NDT | Q5: Oleo | R5: EE Insat | S5: Cinza | T5: CNF | U5: Amido | V5: kd Amido | W5: Met | X5: Lys | Y5: Ca | Z5: P | AA5: Mg | AB5: K | AC5: S | AD5: Na | AE5: Cl | AF5: Co | AG5: Cu | AH5: Mn | AI5: Zn | AJ5: Se | AK5: I | AL5: Fe | AM5: Vit A | AN5: Vit D3 | AO5: Vit E | AP5: Biotina | AQ5: Monensina | AR5: Cr | AS5: Levedura
A6: x | B6: =VLOOKUP($A6,Alimentos!$A:$BA,2,FALSE) -> 0 | C6: =VLOOKUP($A6,Alimentos!$A:$BA,4,FALSE) -> 0 | E6: =VLOOKUP($A6,Alimentos!$A:$BA,5,FALSE) -> 0 | F6: =VLOOKUP($A6,Alimentos!$A:$BA,6,FALSE) -> 0 | G6: =VLOOKUP($A6,Alimentos!$A:$BA,7,FALSE) -> 0 | H6: =VLOOKUP($A6,Alimentos!$A:$BA,8,FALSE) -> 0 | I6: =VLOOKUP($A6,Alimentos!$A:$BA,9,FALSE) -> 0 | J6: =VLOOKUP($A6,Alimentos!$A:$BA,10,FALSE) -> 0 | K6: =VLOOKUP($A6,Alimentos!$A:$BA,11,FALSE) -> 0 | L6: =VLOOKUP($A6,Alimentos!$A:$BA,12,FALSE) -> 0 | M6: =VLOOKUP($A6,Alimentos!$A:$BA,13,FALSE) -> 0 | N6: =VLOOKUP($A6,Alimentos!$A:$BA,14,FALSE) -> 0 | O6: =VLOOKUP($A6,Alimentos!$A:$BA,15,FALSE) -> 0 | P6: =VLOOKUP($A6,Alimentos!$A:$BA,16,FALSE) -> 0 | Q6: =VLOOKUP($A6,Alimentos!$A:$BA,17,FALSE) -> 0 | R6: =VLOOKUP($A6,Alimentos!$A:$BA,18,FALSE) -> 0 | S6: =VLOOKUP($A6,Alimentos!$A:$BA,19,FALSE) -> 0 | T6: =VLOOKUP($A6,Alimentos!$A:$BA,20,FALSE) -> 0 | U6: =VLOOKUP($A6,Alimentos!$A:$BA,21,FALSE) -> 0 | V6: =VLOOKUP($A6,Alimentos!$A:$BA,22,FALSE) -> 0 | W6: =VLOOKUP($A6,Alimentos!$A:$BA,23,FALSE) -> 0 | X6: =VLOOKUP($A6,Alimentos!$A:$BA,24,FALSE) -> 0 | Y6: =VLOOKUP($A6,Alimentos!$A:$BA,25,FALSE) -> 0 | Z6: =VLOOKUP($A6,Alimentos!$A:$BA,26,FALSE) -> 0 | AA6: =VLOOKUP($A6,Alimentos!$A:$BA,27,FALSE) -> 0 | AB6: =VLOOKUP($A6,Alimentos!$A:$BA,28,FALSE) -> 0 | AC6: =VLOOKUP($A6,Alimentos!$A:$BA,29,FALSE) -> 0 | AD6: =VLOOKUP($A6,Alimentos!$A:$BA,30,FALSE) -> 0 | AE6: =VLOOKUP($A6,Alimentos!$A:$BA,31,FALSE) -> 0 | AF6: =VLOOKUP($A6,Alimentos!$A:$BA,32,FALSE) -> 0 | AG6: =VLOOKUP($A6,Alimentos!$A:$BA,33,FALSE) -> 0 | AH6: =VLOOKUP($A6,Alimentos!$A:$BA,34,FALSE) -> 0 | AI6: =VLOOKUP($A6,Alimentos!$A:$BA,35,FALSE) -> 0 | AJ6: =VLOOKUP($A6,Alimentos!$A:$BA,36,FALSE) -> 0 | AK6: =VLOOKUP($A6,Alimentos!$A:$BA,37,FALSE) -> 0 | AL6: =VLOOKUP($A6,Alimentos!$A:$BA,38,FALSE) -> 0 | AM6: =VLOOKUP($A6,Alimentos!$A:$BA,39,FALSE) -> 0 | AN6: =VLOOKUP($A6,Alimentos!$A:$BA,40,FALSE) -> 0 | AO6: =VLOOKUP($A6,Alimentos!$A:$BA,41,FALSE) -> 0 | AP6: =VLOOKUP($A6,Alimentos!$A:$BA,42,FALSE) -> 0 | AQ6: =VLOOKUP($A6,Alimentos!$A:$BA,43,FALSE) -> 0 | AR6: =VLOOKUP($A6,Alimentos!$A:$BA,44,FALSE) -> 0 | AS6: =VLOOKUP($A6,Alimentos!$A:$BA,45,FALSE) -> 0
A7: x | B7: =VLOOKUP($A7,Alimentos!$A:$BA,2,FALSE) -> 0 | C7: =VLOOKUP($A7,Alimentos!$A:$BA,4,FALSE) -> 0 | E7: =VLOOKUP($A7,Alimentos!$A:$BA,5,FALSE) -> 0 | F7: =VLOOKUP($A7,Alimentos!$A:$BA,6,FALSE) -> 0 | G7: =VLOOKUP($A7,Alimentos!$A:$BA,7,FALSE) -> 0 | H7: =VLOOKUP($A7,Alimentos!$A:$BA,8,FALSE) -> 0 | I7: =VLOOKUP($A7,Alimentos!$A:$BA,9,FALSE) -> 0 | J7: =VLOOKUP($A7,Alimentos!$A:$BA,10,FALSE) -> 0 | K7: =VLOOKUP($A7,Alimentos!$A:$BA,11,FALSE) -> 0 | L7: =VLOOKUP($A7,Alimentos!$A:$BA,12,FALSE) -> 0 | M7: =VLOOKUP($A7,Alimentos!$A:$BA,13,FALSE) -> 0 | N7: =VLOOKUP($A7,Alimentos!$A:$BA,14,FALSE) -> 0 | O7: =VLOOKUP($A7,Alimentos!$A:$BA,15,FALSE) -> 0 | P7: =VLOOKUP($A7,Alimentos!$A:$BA,16,FALSE) -> 0 | Q7: =VLOOKUP($A7,Alimentos!$A:$BA,17,FALSE) -> 0 | R7: =VLOOKUP($A7,Alimentos!$A:$BA,18,FALSE) -> 0 | S7: =VLOOKUP($A7,Alimentos!$A:$BA,19,FALSE) -> 0 | T7: =VLOOKUP($A7,Alimentos!$A:$BA,20,FALSE) -> 0 | U7: =VLOOKUP($A7,Alimentos!$A:$BA,21,FALSE) -> 0 | V7: =VLOOKUP($A7,Alimentos!$A:$BA,22,FALSE) -> 0 | W7: =VLOOKUP($A7,Alimentos!$A:$BA,23,FALSE) -> 0 | X7: =VLOOKUP($A7,Alimentos!$A:$BA,24,FALSE) -> 0 | Y7: =VLOOKUP($A7,Alimentos!$A:$BA,25,FALSE) -> 0 | Z7: =VLOOKUP($A7,Alimentos!$A:$BA,26,FALSE) -> 0 | AA7: =VLOOKUP($A7,Alimentos!$A:$BA,27,FALSE) -> 0 | AB7: =VLOOKUP($A7,Alimentos!$A:$BA,28,FALSE) -> 0 | AC7: =VLOOKUP($A7,Alimentos!$A:$BA,29,FALSE) -> 0 | AD7: =VLOOKUP($A7,Alimentos!$A:$BA,30,FALSE) -> 0 | AE7: =VLOOKUP($A7,Alimentos!$A:$BA,31,FALSE) -> 0 | AF7: =VLOOKUP($A7,Alimentos!$A:$BA,32,FALSE) -> 0 | AG7: =VLOOKUP($A7,Alimentos!$A:$BA,33,FALSE) -> 0 | AH7: =VLOOKUP($A7,Alimentos!$A:$BA,34,FALSE) -> 0 | AI7: =VLOOKUP($A7,Alimentos!$A:$BA,35,FALSE) -> 0 | AJ7: =VLOOKUP($A7,Alimentos!$A:$BA,36,FALSE) -> 0 | AK7: =VLOOKUP($A7,Alimentos!$A:$BA,37,FALSE) -> 0 | AL7: =VLOOKUP($A7,Alimentos!$A:$BA,38,FALSE) -> 0 | AM7: =VLOOKUP($A7,Alimentos!$A:$BA,39,FALSE) -> 0 | AN7: =VLOOKUP($A7,Alimentos!$A:$BA,40,FALSE) -> 0 | AO7: =VLOOKUP($A7,Alimentos!$A:$BA,41,FALSE) -> 0 | AP7: =VLOOKUP($A7,Alimentos!$A:$BA,42,FALSE) -> 0 | AQ7: =VLOOKUP($A7,Alimentos!$A:$BA,43,FALSE) -> 0 | AR7: =VLOOKUP($A7,Alimentos!$A:$BA,44,FALSE) -> 0 | AS7: =VLOOKUP($A7,Alimentos!$A:$BA,45,FALSE) -> 0
A8: x | B8: =VLOOKUP($A8,Alimentos!$A:$BA,2,FALSE) -> 0 | C8: =VLOOKUP($A8,Alimentos!$A:$BA,4,FALSE) -> 0 | E8: =VLOOKUP($A8,Alimentos!$A:$BA,5,FALSE) -> 0 | F8: =VLOOKUP($A8,Alimentos!$A:$BA,6,FALSE) -> 0 | G8: =VLOOKUP($A8,Alimentos!$A:$BA,7,FALSE) -> 0 | H8: =VLOOKUP($A8,Alimentos!$A:$BA,8,FALSE) -> 0 | I8: =VLOOKUP($A8,Alimentos!$A:$BA,9,FALSE) -> 0 | J8: =VLOOKUP($A8,Alimentos!$A:$BA,10,FALSE) -> 0 | K8: =VLOOKUP($A8,Alimentos!$A:$BA,11,FALSE) -> 0 | L8: =VLOOKUP($A8,Alimentos!$A:$BA,12,FALSE) -> 0 | M8: =VLOOKUP($A8,Alimentos!$A:$BA,13,FALSE) -> 0 | N8: =VLOOKUP($A8,Alimentos!$A:$BA,14,FALSE) -> 0 | O8: =VLOOKUP($A8,Alimentos!$A:$BA,15,FALSE) -> 0 | P8: =VLOOKUP($A8,Alimentos!$A:$BA,16,FALSE) -> 0 | Q8: =VLOOKUP($A8,Alimentos!$A:$BA,17,FALSE) -> 0 | R8: =VLOOKUP($A8,Alimentos!$A:$BA,18,FALSE) -> 0 | S8: =VLOOKUP($A8,Alimentos!$A:$BA,19,FALSE) -> 0 | T8: =VLOOKUP($A8,Alimentos!$A:$BA,20,FALSE) -> 0 | U8: =VLOOKUP($A8,Alimentos!$A:$BA,21,FALSE) -> 0 | V8: =VLOOKUP($A8,Alimentos!$A:$BA,22,FALSE) -> 0 | W8: =VLOOKUP($A8,Alimentos!$A:$BA,23,FALSE) -> 0 | X8: =VLOOKUP($A8,Alimentos!$A:$BA,24,FALSE) -> 0 | Y8: =VLOOKUP($A8,Alimentos!$A:$BA,25,FALSE) -> 0 | Z8: =VLOOKUP($A8,Alimentos!$A:$BA,26,FALSE) -> 0 | AA8: =VLOOKUP($A8,Alimentos!$A:$BA,27,FALSE) -> 0 | AB8: =VLOOKUP($A8,Alimentos!$A:$BA,28,FALSE) -> 0 | AC8: =VLOOKUP($A8,Alimentos!$A:$BA,29,FALSE) -> 0 | AD8: =VLOOKUP($A8,Alimentos!$A:$BA,30,FALSE) -> 0 | AE8: =VLOOKUP($A8,Alimentos!$A:$BA,31,FALSE) -> 0 | AF8: =VLOOKUP($A8,Alimentos!$A:$BA,32,FALSE) -> 0 | AG8: =VLOOKUP($A8,Alimentos!$A:$BA,33,FALSE) -> 0 | AH8: =VLOOKUP($A8,Alimentos!$A:$BA,34,FALSE) -> 0 | AI8: =VLOOKUP($A8,Alimentos!$A:$BA,35,FALSE) -> 0 | AJ8: =VLOOKUP($A8,Alimentos!$A:$BA,36,FALSE) -> 0 | AK8: =VLOOKUP($A8,Alimentos!$A:$BA,37,FALSE) -> 0 | AL8: =VLOOKUP($A8,Alimentos!$A:$BA,38,FALSE) -> 0 | AM8: =VLOOKUP($A8,Alimentos!$A:$BA,39,FALSE) -> 0 | AN8: =VLOOKUP($A8,Alimentos!$A:$BA,40,FALSE) -> 0 | AO8: =VLOOKUP($A8,Alimentos!$A:$BA,41,FALSE) -> 0 | AP8: =VLOOKUP($A8,Alimentos!$A:$BA,42,FALSE) -> 0 | AQ8: =VLOOKUP($A8,Alimentos!$A:$BA,43,FALSE) -> 0 | AR8: =VLOOKUP($A8,Alimentos!$A:$BA,44,FALSE) -> 0 | AS8: =VLOOKUP($A8,Alimentos!$A:$BA,45,FALSE) -> 0
A9: x | B9: =VLOOKUP($A9,Alimentos!$A:$BA,2,FALSE) -> 0 | C9: =VLOOKUP($A9,Alimentos!$A:$BA,4,FALSE) -> 0 | E9: =VLOOKUP($A9,Alimentos!$A:$BA,5,FALSE) -> 0 | F9: =VLOOKUP($A9,Alimentos!$A:$BA,6,FALSE) -> 0 | G9: =VLOOKUP($A9,Alimentos!$A:$BA,7,FALSE) -> 0 | H9: =VLOOKUP($A9,Alimentos!$A:$BA,8,FALSE) -> 0 | I9: =VLOOKUP($A9,Alimentos!$A:$BA,9,FALSE) -> 0 | J9: =VLOOKUP($A9,Alimentos!$A:$BA,10,FALSE) -> 0 | K9: =VLOOKUP($A9,Alimentos!$A:$BA,11,FALSE) -> 0 | L9: =VLOOKUP($A9,Alimentos!$A:$BA,12,FALSE) -> 0 | M9: =VLOOKUP($A9,Alimentos!$A:$BA,13,FALSE) -> 0 | N9: =VLOOKUP($A9,Alimentos!$A:$BA,14,FALSE) -> 0 | O9: =VLOOKUP($A9,Alimentos!$A:$BA,15,FALSE) -> 0 | P9: =VLOOKUP($A9,Alimentos!$A:$BA,16,FALSE) -> 0 | Q9: =VLOOKUP($A9,Alimentos!$A:$BA,17,FALSE) -> 0 | R9: =VLOOKUP($A9,Alimentos!$A:$BA,18,FALSE) -> 0 | S9: =VLOOKUP($A9,Alimentos!$A:$BA,19,FALSE) -> 0 | T9: =VLOOKUP($A9,Alimentos!$A:$BA,20,FALSE) -> 0 | U9: =VLOOKUP($A9,Alimentos!$A:$BA,21,FALSE) -> 0 | V9: =VLOOKUP($A9,Alimentos!$A:$BA,22,FALSE) -> 0 | W9: =VLOOKUP($A9,Alimentos!$A:$BA,23,FALSE) -> 0 | X9: =VLOOKUP($A9,Alimentos!$A:$BA,24,FALSE) -> 0 | Y9: =VLOOKUP($A9,Alimentos!$A:$BA,25,FALSE) -> 0 | Z9: =VLOOKUP($A9,Alimentos!$A:$BA,26,FALSE) -> 0 | AA9: =VLOOKUP($A9,Alimentos!$A:$BA,27,FALSE) -> 0 | AB9: =VLOOKUP($A9,Alimentos!$A:$BA,28,FALSE) -> 0 | AC9: =VLOOKUP($A9,Alimentos!$A:$BA,29,FALSE) -> 0 | AD9: =VLOOKUP($A9,Alimentos!$A:$BA,30,FALSE) -> 0 | AE9: =VLOOKUP($A9,Alimentos!$A:$BA,31,FALSE) -> 0 | AF9: =VLOOKUP($A9,Alimentos!$A:$BA,32,FALSE) -> 0 | AG9: =VLOOKUP($A9,Alimentos!$A:$BA,33,FALSE) -> 0 | AH9: =VLOOKUP($A9,Alimentos!$A:$BA,34,FALSE) -> 0 | AI9: =VLOOKUP($A9,Alimentos!$A:$BA,35,FALSE) -> 0 | AJ9: =VLOOKUP($A9,Alimentos!$A:$BA,36,FALSE) -> 0 | AK9: =VLOOKUP($A9,Alimentos!$A:$BA,37,FALSE) -> 0 | AL9: =VLOOKUP($A9,Alimentos!$A:$BA,38,FALSE) -> 0 | AM9: =VLOOKUP($A9,Alimentos!$A:$BA,39,FALSE) -> 0 | AN9: =VLOOKUP($A9,Alimentos!$A:$BA,40,FALSE) -> 0 | AO9: =VLOOKUP($A9,Alimentos!$A:$BA,41,FALSE) -> 0 | AP9: =VLOOKUP($A9,Alimentos!$A:$BA,42,FALSE) -> 0 | AQ9: =VLOOKUP($A9,Alimentos!$A:$BA,43,FALSE) -> 0 | AR9: =VLOOKUP($A9,Alimentos!$A:$BA,44,FALSE) -> 0 | AS9: =VLOOKUP($A9,Alimentos!$A:$BA,45,FALSE) -> 0
A10: x | B10: =VLOOKUP($A10,Alimentos!$A:$BA,2,FALSE) -> 0 | C10: =VLOOKUP($A10,Alimentos!$A:$BA,4,FALSE) -> 0 | E10: =VLOOKUP($A10,Alimentos!$A:$BA,5,FALSE) -> 0 | F10: =VLOOKUP($A10,Alimentos!$A:$BA,6,FALSE) -> 0 | G10: =VLOOKUP($A10,Alimentos!$A:$BA,7,FALSE) -> 0 | H10: =VLOOKUP($A10,Alimentos!$A:$BA,8,FALSE) -> 0 | I10: =VLOOKUP($A10,Alimentos!$A:$BA,9,FALSE) -> 0 | J10: =VLOOKUP($A10,Alimentos!$A:$BA,10,FALSE) -> 0 | K10: =VLOOKUP($A10,Alimentos!$A:$BA,11,FALSE) -> 0 | L10: =VLOOKUP($A10,Alimentos!$A:$BA,12,FALSE) -> 0 | M10: =VLOOKUP($A10,Alimentos!$A:$BA,13,FALSE) -> 0 | N10: =VLOOKUP($A10,Alimentos!$A:$BA,14,FALSE) -> 0 | O10: =VLOOKUP($A10,Alimentos!$A:$BA,15,FALSE) -> 0 | P10: =VLOOKUP($A10,Alimentos!$A:$BA,16,FALSE) -> 0 | Q10: =VLOOKUP($A10,Alimentos!$A:$BA,17,FALSE) -> 0 | R10: =VLOOKUP($A10,Alimentos!$A:$BA,18,FALSE) -> 0 | S10: =VLOOKUP($A10,Alimentos!$A:$BA,19,FALSE) -> 0 | T10: =VLOOKUP($A10,Alimentos!$A:$BA,20,FALSE) -> 0 | U10: =VLOOKUP($A10,Alimentos!$A:$BA,21,FALSE) -> 0 | V10: =VLOOKUP($A10,Alimentos!$A:$BA,22,FALSE) -> 0 | W10: =VLOOKUP($A10,Alimentos!$A:$BA,23,FALSE) -> 0 | X10: =VLOOKUP($A10,Alimentos!$A:$BA,24,FALSE) -> 0 | Y10: =VLOOKUP($A10,Alimentos!$A:$BA,25,FALSE) -> 0 | Z10: =VLOOKUP($A10,Alimentos!$A:$BA,26,FALSE) -> 0 | AA10: =VLOOKUP($A10,Alimentos!$A:$BA,27,FALSE) -> 0 | AB10: =VLOOKUP($A10,Alimentos!$A:$BA,28,FALSE) -> 0 | AC10: =VLOOKUP($A10,Alimentos!$A:$BA,29,FALSE) -> 0 | AD10: =VLOOKUP($A10,Alimentos!$A:$BA,30,FALSE) -> 0 | AE10: =VLOOKUP($A10,Alimentos!$A:$BA,31,FALSE) -> 0 | AF10: =VLOOKUP($A10,Alimentos!$A:$BA,32,FALSE) -> 0 | AG10: =VLOOKUP($A10,Alimentos!$A:$BA,33,FALSE) -> 0 | AH10: =VLOOKUP($A10,Alimentos!$A:$BA,34,FALSE) -> 0 | AI10: =VLOOKUP($A10,Alimentos!$A:$BA,35,FALSE) -> 0 | AJ10: =VLOOKUP($A10,Alimentos!$A:$BA,36,FALSE) -> 0 | AK10: =VLOOKUP($A10,Alimentos!$A:$BA,37,FALSE) -> 0 | AL10: =VLOOKUP($A10,Alimentos!$A:$BA,38,FALSE) -> 0 | AM10: =VLOOKUP($A10,Alimentos!$A:$BA,39,FALSE) -> 0 | AN10: =VLOOKUP($A10,Alimentos!$A:$BA,40,FALSE) -> 0 | AO10: =VLOOKUP($A10,Alimentos!$A:$BA,41,FALSE) -> 0 | AP10: =VLOOKUP($A10,Alimentos!$A:$BA,42,FALSE) -> 0 | AQ10: =VLOOKUP($A10,Alimentos!$A:$BA,43,FALSE) -> 0 | AR10: =VLOOKUP($A10,Alimentos!$A:$BA,44,FALSE) -> 0 | AS10: =VLOOKUP($A10,Alimentos!$A:$BA,45,FALSE) -> 0
A11: x | B11: =VLOOKUP($A11,Alimentos!$A:$BA,2,FALSE) -> 0 | C11: =VLOOKUP($A11,Alimentos!$A:$BA,4,FALSE) -> 0 | E11: =VLOOKUP($A11,Alimentos!$A:$BA,5,FALSE) -> 0 | F11: =VLOOKUP($A11,Alimentos!$A:$BA,6,FALSE) -> 0 | G11: =VLOOKUP($A11,Alimentos!$A:$BA,7,FALSE) -> 0 | H11: =VLOOKUP($A11,Alimentos!$A:$BA,8,FALSE) -> 0 | I11: =VLOOKUP($A11,Alimentos!$A:$BA,9,FALSE) -> 0 | J11: =VLOOKUP($A11,Alimentos!$A:$BA,10,FALSE) -> 0 | K11: =VLOOKUP($A11,Alimentos!$A:$BA,11,FALSE) -> 0 | L11: =VLOOKUP($A11,Alimentos!$A:$BA,12,FALSE) -> 0 | M11: =VLOOKUP($A11,Alimentos!$A:$BA,13,FALSE) -> 0 | N11: =VLOOKUP($A11,Alimentos!$A:$BA,14,FALSE) -> 0 | O11: =VLOOKUP($A11,Alimentos!$A:$BA,15,FALSE) -> 0 | P11: =VLOOKUP($A11,Alimentos!$A:$BA,16,FALSE) -> 0 | Q11: =VLOOKUP($A11,Alimentos!$A:$BA,17,FALSE) -> 0 | R11: =VLOOKUP($A11,Alimentos!$A:$BA,18,FALSE) -> 0 | S11: =VLOOKUP($A11,Alimentos!$A:$BA,19,FALSE) -> 0 | T11: =VLOOKUP($A11,Alimentos!$A:$BA,20,FALSE) -> 0 | U11: =VLOOKUP($A11,Alimentos!$A:$BA,21,FALSE) -> 0 | V11: =VLOOKUP($A11,Alimentos!$A:$BA,22,FALSE) -> 0 | W11: =VLOOKUP($A11,Alimentos!$A:$BA,23,FALSE) -> 0 | X11: =VLOOKUP($A11,Alimentos!$A:$BA,24,FALSE) -> 0 | Y11: =VLOOKUP($A11,Alimentos!$A:$BA,25,FALSE) -> 0 | Z11: =VLOOKUP($A11,Alimentos!$A:$BA,26,FALSE) -> 0 | AA11: =VLOOKUP($A11,Alimentos!$A:$BA,27,FALSE) -> 0 | AB11: =VLOOKUP($A11,Alimentos!$A:$BA,28,FALSE) -> 0 | AC11: =VLOOKUP($A11,Alimentos!$A:$BA,29,FALSE) -> 0 | AD11: =VLOOKUP($A11,Alimentos!$A:$BA,30,FALSE) -> 0 | AE11: =VLOOKUP($A11,Alimentos!$A:$BA,31,FALSE) -> 0 | AF11: =VLOOKUP($A11,Alimentos!$A:$BA,32,FALSE) -> 0 | AG11: =VLOOKUP($A11,Alimentos!$A:$BA,33,FALSE) -> 0 | AH11: =VLOOKUP($A11,Alimentos!$A:$BA,34,FALSE) -> 0 | AI11: =VLOOKUP($A11,Alimentos!$A:$BA,35,FALSE) -> 0 | AJ11: =VLOOKUP($A11,Alimentos!$A:$BA,36,FALSE) -> 0 | AK11: =VLOOKUP($A11,Alimentos!$A:$BA,37,FALSE) -> 0 | AL11: =VLOOKUP($A11,Alimentos!$A:$BA,38,FALSE) -> 0 | AM11: =VLOOKUP($A11,Alimentos!$A:$BA,39,FALSE) -> 0 | AN11: =VLOOKUP($A11,Alimentos!$A:$BA,40,FALSE) -> 0 | AO11: =VLOOKUP($A11,Alimentos!$A:$BA,41,FALSE) -> 0 | AP11: =VLOOKUP($A11,Alimentos!$A:$BA,42,FALSE) -> 0 | AQ11: =VLOOKUP($A11,Alimentos!$A:$BA,43,FALSE) -> 0 | AR11: =VLOOKUP($A11,Alimentos!$A:$BA,44,FALSE) -> 0 | AS11: =VLOOKUP($A11,Alimentos!$A:$BA,45,FALSE) -> 0
A12: x | B12: =VLOOKUP($A12,Alimentos!$A:$BA,2,FALSE) -> 0 | C12: =VLOOKUP($A12,Alimentos!$A:$BA,4,FALSE) -> 0 | E12: =VLOOKUP($A12,Alimentos!$A:$BA,5,FALSE) -> 0 | F12: =VLOOKUP($A12,Alimentos!$A:$BA,6,FALSE) -> 0 | G12: =VLOOKUP($A12,Alimentos!$A:$BA,7,FALSE) -> 0 | H12: =VLOOKUP($A12,Alimentos!$A:$BA,8,FALSE) -> 0 | I12: =VLOOKUP($A12,Alimentos!$A:$BA,9,FALSE) -> 0 | J12: =VLOOKUP($A12,Alimentos!$A:$BA,10,FALSE) -> 0 | K12: =VLOOKUP($A12,Alimentos!$A:$BA,11,FALSE) -> 0 | L12: =VLOOKUP($A12,Alimentos!$A:$BA,12,FALSE) -> 0 | M12: =VLOOKUP($A12,Alimentos!$A:$BA,13,FALSE) -> 0 | N12: =VLOOKUP($A12,Alimentos!$A:$BA,14,FALSE) -> 0 | O12: =VLOOKUP($A12,Alimentos!$A:$BA,15,FALSE) -> 0 | P12: =VLOOKUP($A12,Alimentos!$A:$BA,16,FALSE) -> 0 | Q12: =VLOOKUP($A12,Alimentos!$A:$BA,17,FALSE) -> 0 | R12: =VLOOKUP($A12,Alimentos!$A:$BA,18,FALSE) -> 0 | S12: =VLOOKUP($A12,Alimentos!$A:$BA,19,FALSE) -> 0 | T12: =VLOOKUP($A12,Alimentos!$A:$BA,20,FALSE) -> 0 | U12: =VLOOKUP($A12,Alimentos!$A:$BA,21,FALSE) -> 0 | V12: =VLOOKUP($A12,Alimentos!$A:$BA,22,FALSE) -> 0 | W12: =VLOOKUP($A12,Alimentos!$A:$BA,23,FALSE) -> 0 | X12: =VLOOKUP($A12,Alimentos!$A:$BA,24,FALSE) -> 0 | Y12: =VLOOKUP($A12,Alimentos!$A:$BA,25,FALSE) -> 0 | Z12: =VLOOKUP($A12,Alimentos!$A:$BA,26,FALSE) -> 0 | AA12: =VLOOKUP($A12,Alimentos!$A:$BA,27,FALSE) -> 0 | AB12: =VLOOKUP($A12,Alimentos!$A:$BA,28,FALSE) -> 0 | AC12: =VLOOKUP($A12,Alimentos!$A:$BA,29,FALSE) -> 0 | AD12: =VLOOKUP($A12,Alimentos!$A:$BA,30,FALSE) -> 0 | AE12: =VLOOKUP($A12,Alimentos!$A:$BA,31,FALSE) -> 0 | AF12: =VLOOKUP($A12,Alimentos!$A:$BA,32,FALSE) -> 0 | AG12: =VLOOKUP($A12,Alimentos!$A:$BA,33,FALSE) -> 0 | AH12: =VLOOKUP($A12,Alimentos!$A:$BA,34,FALSE) -> 0 | AI12: =VLOOKUP($A12,Alimentos!$A:$BA,35,FALSE) -> 0 | AJ12: =VLOOKUP($A12,Alimentos!$A:$BA,36,FALSE) -> 0 | AK12: =VLOOKUP($A12,Alimentos!$A:$BA,37,FALSE) -> 0 | AL12: =VLOOKUP($A12,Alimentos!$A:$BA,38,FALSE) -> 0 | AM12: =VLOOKUP($A12,Alimentos!$A:$BA,39,FALSE) -> 0 | AN12: =VLOOKUP($A12,Alimentos!$A:$BA,40,FALSE) -> 0 | AO12: =VLOOKUP($A12,Alimentos!$A:$BA,41,FALSE) -> 0 | AP12: =VLOOKUP($A12,Alimentos!$A:$BA,42,FALSE) -> 0 | AQ12: =VLOOKUP($A12,Alimentos!$A:$BA,43,FALSE) -> 0 | AR12: =VLOOKUP($A12,Alimentos!$A:$BA,44,FALSE) -> 0 | AS12: =VLOOKUP($A12,Alimentos!$A:$BA,45,FALSE) -> 0
A13: x | B13: =VLOOKUP($A13,Alimentos!$A:$BA,2,FALSE) -> 0 | C13: =VLOOKUP($A13,Alimentos!$A:$BA,4,FALSE) -> 0 | E13: =VLOOKUP($A13,Alimentos!$A:$BA,5,FALSE) -> 0 | F13: =VLOOKUP($A13,Alimentos!$A:$BA,6,FALSE) -> 0 | G13: =VLOOKUP($A13,Alimentos!$A:$BA,7,FALSE) -> 0 | H13: =VLOOKUP($A13,Alimentos!$A:$BA,8,FALSE) -> 0 | I13: =VLOOKUP($A13,Alimentos!$A:$BA,9,FALSE) -> 0 | J13: =VLOOKUP($A13,Alimentos!$A:$BA,10,FALSE) -> 0 | K13: =VLOOKUP($A13,Alimentos!$A:$BA,11,FALSE) -> 0 | L13: =VLOOKUP($A13,Alimentos!$A:$BA,12,FALSE) -> 0 | M13: =VLOOKUP($A13,Alimentos!$A:$BA,13,FALSE) -> 0 | N13: =VLOOKUP($A13,Alimentos!$A:$BA,14,FALSE) -> 0 | O13: =VLOOKUP($A13,Alimentos!$A:$BA,15,FALSE) -> 0 | P13: =VLOOKUP($A13,Alimentos!$A:$BA,16,FALSE) -> 0 | Q13: =VLOOKUP($A13,Alimentos!$A:$BA,17,FALSE) -> 0 | R13: =VLOOKUP($A13,Alimentos!$A:$BA,18,FALSE) -> 0 | S13: =VLOOKUP($A13,Alimentos!$A:$BA,19,FALSE) -> 0 | T13: =VLOOKUP($A13,Alimentos!$A:$BA,20,FALSE) -> 0 | U13: =VLOOKUP($A13,Alimentos!$A:$BA,21,FALSE) -> 0 | V13: =VLOOKUP($A13,Alimentos!$A:$BA,22,FALSE) -> 0 | W13: =VLOOKUP($A13,Alimentos!$A:$BA,23,FALSE) -> 0 | X13: =VLOOKUP($A13,Alimentos!$A:$BA,24,FALSE) -> 0 | Y13: =VLOOKUP($A13,Alimentos!$A:$BA,25,FALSE) -> 0 | Z13: =VLOOKUP($A13,Alimentos!$A:$BA,26,FALSE) -> 0 | AA13: =VLOOKUP($A13,Alimentos!$A:$BA,27,FALSE) -> 0 | AB13: =VLOOKUP($A13,Alimentos!$A:$BA,28,FALSE) -> 0 | AC13: =VLOOKUP($A13,Alimentos!$A:$BA,29,FALSE) -> 0 | AD13: =VLOOKUP($A13,Alimentos!$A:$BA,30,FALSE) -> 0 | AE13: =VLOOKUP($A13,Alimentos!$A:$BA,31,FALSE) -> 0 | AF13: =VLOOKUP($A13,Alimentos!$A:$BA,32,FALSE) -> 0 | AG13: =VLOOKUP($A13,Alimentos!$A:$BA,33,FALSE) -> 0 | AH13: =VLOOKUP($A13,Alimentos!$A:$BA,34,FALSE) -> 0 | AI13: =VLOOKUP($A13,Alimentos!$A:$BA,35,FALSE) -> 0 | AJ13: =VLOOKUP($A13,Alimentos!$A:$BA,36,FALSE) -> 0 | AK13: =VLOOKUP($A13,Alimentos!$A:$BA,37,FALSE) -> 0 | AL13: =VLOOKUP($A13,Alimentos!$A:$BA,38,FALSE) -> 0 | AM13: =VLOOKUP($A13,Alimentos!$A:$BA,39,FALSE) -> 0 | AN13: =VLOOKUP($A13,Alimentos!$A:$BA,40,FALSE) -> 0 | AO13: =VLOOKUP($A13,Alimentos!$A:$BA,41,FALSE) -> 0 | AP13: =VLOOKUP($A13,Alimentos!$A:$BA,42,FALSE) -> 0 | AQ13: =VLOOKUP($A13,Alimentos!$A:$BA,43,FALSE) -> 0 | AR13: =VLOOKUP($A13,Alimentos!$A:$BA,44,FALSE) -> 0 | AS13: =VLOOKUP($A13,Alimentos!$A:$BA,45,FALSE) -> 0
A14: x | B14: =VLOOKUP($A14,Alimentos!$A:$BA,2,FALSE) -> 0 | C14: =VLOOKUP($A14,Alimentos!$A:$BA,4,FALSE) -> 0 | E14: =VLOOKUP($A14,Alimentos!$A:$BA,5,FALSE) -> 0 | F14: =VLOOKUP($A14,Alimentos!$A:$BA,6,FALSE) -> 0 | G14: =VLOOKUP($A14,Alimentos!$A:$BA,7,FALSE) -> 0 | H14: =VLOOKUP($A14,Alimentos!$A:$BA,8,FALSE) -> 0 | I14: =VLOOKUP($A14,Alimentos!$A:$BA,9,FALSE) -> 0 | J14: =VLOOKUP($A14,Alimentos!$A:$BA,10,FALSE) -> 0 | K14: =VLOOKUP($A14,Alimentos!$A:$BA,11,FALSE) -> 0 | L14: =VLOOKUP($A14,Alimentos!$A:$BA,12,FALSE) -> 0 | M14: =VLOOKUP($A14,Alimentos!$A:$BA,13,FALSE) -> 0 | N14: =VLOOKUP($A14,Alimentos!$A:$BA,14,FALSE) -> 0 | O14: =VLOOKUP($A14,Alimentos!$A:$BA,15,FALSE) -> 0 | P14: =VLOOKUP($A14,Alimentos!$A:$BA,16,FALSE) -> 0 | Q14: =VLOOKUP($A14,Alimentos!$A:$BA,17,FALSE) -> 0 | R14: =VLOOKUP($A14,Alimentos!$A:$BA,18,FALSE) -> 0 | S14: =VLOOKUP($A14,Alimentos!$A:$BA,19,FALSE) -> 0 | T14: =VLOOKUP($A14,Alimentos!$A:$BA,20,FALSE) -> 0 | U14: =VLOOKUP($A14,Alimentos!$A:$BA,21,FALSE) -> 0 | V14: =VLOOKUP($A14,Alimentos!$A:$BA,22,FALSE) -> 0 | W14: =VLOOKUP($A14,Alimentos!$A:$BA,23,FALSE) -> 0 | X14: =VLOOKUP($A14,Alimentos!$A:$BA,24,FALSE) -> 0 | Y14: =VLOOKUP($A14,Alimentos!$A:$BA,25,FALSE) -> 0 | Z14: =VLOOKUP($A14,Alimentos!$A:$BA,26,FALSE) -> 0 | AA14: =VLOOKUP($A14,Alimentos!$A:$BA,27,FALSE) -> 0 | AB14: =VLOOKUP($A14,Alimentos!$A:$BA,28,FALSE) -> 0 | AC14: =VLOOKUP($A14,Alimentos!$A:$BA,29,FALSE) -> 0 | AD14: =VLOOKUP($A14,Alimentos!$A:$BA,30,FALSE) -> 0 | AE14: =VLOOKUP($A14,Alimentos!$A:$BA,31,FALSE) -> 0 | AF14: =VLOOKUP($A14,Alimentos!$A:$BA,32,FALSE) -> 0 | AG14: =VLOOKUP($A14,Alimentos!$A:$BA,33,FALSE) -> 0 | AH14: =VLOOKUP($A14,Alimentos!$A:$BA,34,FALSE) -> 0 | AI14: =VLOOKUP($A14,Alimentos!$A:$BA,35,FALSE) -> 0 | AJ14: =VLOOKUP($A14,Alimentos!$A:$BA,36,FALSE) -> 0 | AK14: =VLOOKUP($A14,Alimentos!$A:$BA,37,FALSE) -> 0 | AL14: =VLOOKUP($A14,Alimentos!$A:$BA,38,FALSE) -> 0 | AM14: =VLOOKUP($A14,Alimentos!$A:$BA,39,FALSE) -> 0 | AN14: =VLOOKUP($A14,Alimentos!$A:$BA,40,FALSE) -> 0 | AO14: =VLOOKUP($A14,Alimentos!$A:$BA,41,FALSE) -> 0 | AP14: =VLOOKUP($A14,Alimentos!$A:$BA,42,FALSE) -> 0 | AQ14: =VLOOKUP($A14,Alimentos!$A:$BA,43,FALSE) -> 0 | AR14: =VLOOKUP($A14,Alimentos!$A:$BA,44,FALSE) -> 0 | AS14: =VLOOKUP($A14,Alimentos!$A:$BA,45,FALSE) -> 0
A15: x | B15: =VLOOKUP($A15,Alimentos!$A:$BA,2,FALSE) -> 0 | C15: =VLOOKUP($A15,Alimentos!$A:$BA,4,FALSE) -> 0 | E15: =VLOOKUP($A15,Alimentos!$A:$BA,5,FALSE) -> 0 | F15: =VLOOKUP($A15,Alimentos!$A:$BA,6,FALSE) -> 0 | G15: =VLOOKUP($A15,Alimentos!$A:$BA,7,FALSE) -> 0 | H15: =VLOOKUP($A15,Alimentos!$A:$BA,8,FALSE) -> 0 | I15: =VLOOKUP($A15,Alimentos!$A:$BA,9,FALSE) -> 0 | J15: =VLOOKUP($A15,Alimentos!$A:$BA,10,FALSE) -> 0 | K15: =VLOOKUP($A15,Alimentos!$A:$BA,11,FALSE) -> 0 | L15: =VLOOKUP($A15,Alimentos!$A:$BA,12,FALSE) -> 0 | M15: =VLOOKUP($A15,Alimentos!$A:$BA,13,FALSE) -> 0 | N15: =VLOOKUP($A15,Alimentos!$A:$BA,14,FALSE) -> 0 | O15: =VLOOKUP($A15,Alimentos!$A:$BA,15,FALSE) -> 0 | P15: =VLOOKUP($A15,Alimentos!$A:$BA,16,FALSE) -> 0 | Q15: =VLOOKUP($A15,Alimentos!$A:$BA,17,FALSE) -> 0 | R15: =VLOOKUP($A15,Alimentos!$A:$BA,18,FALSE) -> 0 | S15: =VLOOKUP($A15,Alimentos!$A:$BA,19,FALSE) -> 0 | T15: =VLOOKUP($A15,Alimentos!$A:$BA,20,FALSE) -> 0 | U15: =VLOOKUP($A15,Alimentos!$A:$BA,21,FALSE) -> 0 | V15: =VLOOKUP($A15,Alimentos!$A:$BA,22,FALSE) -> 0 | W15: =VLOOKUP($A15,Alimentos!$A:$BA,23,FALSE) -> 0 | X15: =VLOOKUP($A15,Alimentos!$A:$BA,24,FALSE) -> 0 | Y15: =VLOOKUP($A15,Alimentos!$A:$BA,25,FALSE) -> 0 | Z15: =VLOOKUP($A15,Alimentos!$A:$BA,26,FALSE) -> 0 | AA15: =VLOOKUP($A15,Alimentos!$A:$BA,27,FALSE) -> 0 | AB15: =VLOOKUP($A15,Alimentos!$A:$BA,28,FALSE) -> 0 | AC15: =VLOOKUP($A15,Alimentos!$A:$BA,29,FALSE) -> 0 | AD15: =VLOOKUP($A15,Alimentos!$A:$BA,30,FALSE) -> 0 | AE15: =VLOOKUP($A15,Alimentos!$A:$BA,31,FALSE) -> 0 | AF15: =VLOOKUP($A15,Alimentos!$A:$BA,32,FALSE) -> 0 | AG15: =VLOOKUP($A15,Alimentos!$A:$BA,33,FALSE) -> 0 | AH15: =VLOOKUP($A15,Alimentos!$A:$BA,34,FALSE) -> 0 | AI15: =VLOOKUP($A15,Alimentos!$A:$BA,35,FALSE) -> 0 | AJ15: =VLOOKUP($A15,Alimentos!$A:$BA,36,FALSE) -> 0 | AK15: =VLOOKUP($A15,Alimentos!$A:$BA,37,FALSE) -> 0 | AL15: =VLOOKUP($A15,Alimentos!$A:$BA,38,FALSE) -> 0 | AM15: =VLOOKUP($A15,Alimentos!$A:$BA,39,FALSE) -> 0 | AN15: =VLOOKUP($A15,Alimentos!$A:$BA,40,FALSE) -> 0 | AO15: =VLOOKUP($A15,Alimentos!$A:$BA,41,FALSE) -> 0 | AP15: =VLOOKUP($A15,Alimentos!$A:$BA,42,FALSE) -> 0 | AQ15: =VLOOKUP($A15,Alimentos!$A:$BA,43,FALSE) -> 0 | AR15: =VLOOKUP($A15,Alimentos!$A:$BA,44,FALSE) -> 0 | AS15: =VLOOKUP($A15,Alimentos!$A:$BA,45,FALSE) -> 0
A16: x | B16: =VLOOKUP($A16,Alimentos!$A:$BA,2,FALSE) -> 0 | C16: =VLOOKUP($A16,Alimentos!$A:$BA,4,FALSE) -> 0 | E16: =VLOOKUP($A16,Alimentos!$A:$BA,5,FALSE) -> 0 | F16: =VLOOKUP($A16,Alimentos!$A:$BA,6,FALSE) -> 0 | G16: =VLOOKUP($A16,Alimentos!$A:$BA,7,FALSE) -> 0 | H16: =VLOOKUP($A16,Alimentos!$A:$BA,8,FALSE) -> 0 | I16: =VLOOKUP($A16,Alimentos!$A:$BA,9,FALSE) -> 0 | J16: =VLOOKUP($A16,Alimentos!$A:$BA,10,FALSE) -> 0 | K16: =VLOOKUP($A16,Alimentos!$A:$BA,11,FALSE) -> 0 | L16: =VLOOKUP($A16,Alimentos!$A:$BA,12,FALSE) -> 0 | M16: =VLOOKUP($A16,Alimentos!$A:$BA,13,FALSE) -> 0 | N16: =VLOOKUP($A16,Alimentos!$A:$BA,14,FALSE) -> 0 | O16: =VLOOKUP($A16,Alimentos!$A:$BA,15,FALSE) -> 0 | P16: =VLOOKUP($A16,Alimentos!$A:$BA,16,FALSE) -> 0 | Q16: =VLOOKUP($A16,Alimentos!$A:$BA,17,FALSE) -> 0 | R16: =VLOOKUP($A16,Alimentos!$A:$BA,18,FALSE) -> 0 | S16: =VLOOKUP($A16,Alimentos!$A:$BA,19,FALSE) -> 0 | T16: =VLOOKUP($A16,Alimentos!$A:$BA,20,FALSE) -> 0 | U16: =VLOOKUP($A16,Alimentos!$A:$BA,21,FALSE) -> 0 | V16: =VLOOKUP($A16,Alimentos!$A:$BA,22,FALSE) -> 0 | W16: =VLOOKUP($A16,Alimentos!$A:$BA,23,FALSE) -> 0 | X16: =VLOOKUP($A16,Alimentos!$A:$BA,24,FALSE) -> 0 | Y16: =VLOOKUP($A16,Alimentos!$A:$BA,25,FALSE) -> 0 | Z16: =VLOOKUP($A16,Alimentos!$A:$BA,26,FALSE) -> 0 | AA16: =VLOOKUP($A16,Alimentos!$A:$BA,27,FALSE) -> 0 | AB16: =VLOOKUP($A16,Alimentos!$A:$BA,28,FALSE) -> 0 | AC16: =VLOOKUP($A16,Alimentos!$A:$BA,29,FALSE) -> 0 | AD16: =VLOOKUP($A16,Alimentos!$A:$BA,30,FALSE) -> 0 | AE16: =VLOOKUP($A16,Alimentos!$A:$BA,31,FALSE) -> 0 | AF16: =VLOOKUP($A16,Alimentos!$A:$BA,32,FALSE) -> 0 | AG16: =VLOOKUP($A16,Alimentos!$A:$BA,33,FALSE) -> 0 | AH16: =VLOOKUP($A16,Alimentos!$A:$BA,34,FALSE) -> 0 | AI16: =VLOOKUP($A16,Alimentos!$A:$BA,35,FALSE) -> 0 | AJ16: =VLOOKUP($A16,Alimentos!$A:$BA,36,FALSE) -> 0 | AK16: =VLOOKUP($A16,Alimentos!$A:$BA,37,FALSE) -> 0 | AL16: =VLOOKUP($A16,Alimentos!$A:$BA,38,FALSE) -> 0 | AM16: =VLOOKUP($A16,Alimentos!$A:$BA,39,FALSE) -> 0 | AN16: =VLOOKUP($A16,Alimentos!$A:$BA,40,FALSE) -> 0 | AO16: =VLOOKUP($A16,Alimentos!$A:$BA,41,FALSE) -> 0 | AP16: =VLOOKUP($A16,Alimentos!$A:$BA,42,FALSE) -> 0 | AQ16: =VLOOKUP($A16,Alimentos!$A:$BA,43,FALSE) -> 0 | AR16: =VLOOKUP($A16,Alimentos!$A:$BA,44,FALSE) -> 0 | AS16: =VLOOKUP($A16,Alimentos!$A:$BA,45,FALSE) -> 0
A17: x | B17: =VLOOKUP($A17,Alimentos!$A:$BA,2,FALSE) -> 0 | C17: =VLOOKUP($A17,Alimentos!$A:$BA,4,FALSE) -> 0 | E17: =VLOOKUP($A17,Alimentos!$A:$BA,5,FALSE) -> 0 | F17: =VLOOKUP($A17,Alimentos!$A:$BA,6,FALSE) -> 0 | G17: =VLOOKUP($A17,Alimentos!$A:$BA,7,FALSE) -> 0 | H17: =VLOOKUP($A17,Alimentos!$A:$BA,8,FALSE) -> 0 | I17: =VLOOKUP($A17,Alimentos!$A:$BA,9,FALSE) -> 0 | J17: =VLOOKUP($A17,Alimentos!$A:$BA,10,FALSE) -> 0 | K17: =VLOOKUP($A17,Alimentos!$A:$BA,11,FALSE) -> 0 | L17: =VLOOKUP($A17,Alimentos!$A:$BA,12,FALSE) -> 0 | M17: =VLOOKUP($A17,Alimentos!$A:$BA,13,FALSE) -> 0 | N17: =VLOOKUP($A17,Alimentos!$A:$BA,14,FALSE) -> 0 | O17: =VLOOKUP($A17,Alimentos!$A:$BA,15,FALSE) -> 0 | P17: =VLOOKUP($A17,Alimentos!$A:$BA,16,FALSE) -> 0 | Q17: =VLOOKUP($A17,Alimentos!$A:$BA,17,FALSE) -> 0 | R17: =VLOOKUP($A17,Alimentos!$A:$BA,18,FALSE) -> 0 | S17: =VLOOKUP($A17,Alimentos!$A:$BA,19,FALSE) -> 0 | T17: =VLOOKUP($A17,Alimentos!$A:$BA,20,FALSE) -> 0 | U17: =VLOOKUP($A17,Alimentos!$A:$BA,21,FALSE) -> 0 | V17: =VLOOKUP($A17,Alimentos!$A:$BA,22,FALSE) -> 0 | W17: =VLOOKUP($A17,Alimentos!$A:$BA,23,FALSE) -> 0 | X17: =VLOOKUP($A17,Alimentos!$A:$BA,24,FALSE) -> 0 | Y17: =VLOOKUP($A17,Alimentos!$A:$BA,25,FALSE) -> 0 | Z17: =VLOOKUP($A17,Alimentos!$A:$BA,26,FALSE) -> 0 | AA17: =VLOOKUP($A17,Alimentos!$A:$BA,27,FALSE) -> 0 | AB17: =VLOOKUP($A17,Alimentos!$A:$BA,28,FALSE) -> 0 | AC17: =VLOOKUP($A17,Alimentos!$A:$BA,29,FALSE) -> 0 | AD17: =VLOOKUP($A17,Alimentos!$A:$BA,30,FALSE) -> 0 | AE17: =VLOOKUP($A17,Alimentos!$A:$BA,31,FALSE) -> 0 | AF17: =VLOOKUP($A17,Alimentos!$A:$BA,32,FALSE) -> 0 | AG17: =VLOOKUP($A17,Alimentos!$A:$BA,33,FALSE) -> 0 | AH17: =VLOOKUP($A17,Alimentos!$A:$BA,34,FALSE) -> 0 | AI17: =VLOOKUP($A17,Alimentos!$A:$BA,35,FALSE) -> 0 | AJ17: =VLOOKUP($A17,Alimentos!$A:$BA,36,FALSE) -> 0 | AK17: =VLOOKUP($A17,Alimentos!$A:$BA,37,FALSE) -> 0 | AL17: =VLOOKUP($A17,Alimentos!$A:$BA,38,FALSE) -> 0 | AM17: =VLOOKUP($A17,Alimentos!$A:$BA,39,FALSE) -> 0 | AN17: =VLOOKUP($A17,Alimentos!$A:$BA,40,FALSE) -> 0 | AO17: =VLOOKUP($A17,Alimentos!$A:$BA,41,FALSE) -> 0 | AP17: =VLOOKUP($A17,Alimentos!$A:$BA,42,FALSE) -> 0 | AQ17: =VLOOKUP($A17,Alimentos!$A:$BA,43,FALSE) -> 0 | AR17: =VLOOKUP($A17,Alimentos!$A:$BA,44,FALSE) -> 0 | AS17: =VLOOKUP($A17,Alimentos!$A:$BA,45,FALSE) -> 0
... A21: x | B21: =VLOOKUP($A21,Alimentos!$A:$BA,2,FALSE) -> 0 | C21: =VLOOKUP($A21,Alimentos!$A:$BA,4,FALSE) -> 0 | E21: =VLOOKUP($A21,Alimentos!$A:$BA,5,FALSE) -> 0 | F21: =VLOOKUP($A21,Alimentos!$A:$BA,6,FALSE) -> 0 | G21: =VLOOKUP($A21,Alimentos!$A:$BA,7,FALSE) -> 0 | H21: =VLOOKUP($A21,Alimentos!$A:$BA,8,FALSE) -> 0 | I21: =VLOOKUP($A21,Alimentos!$A:$BA,9,FALSE) -> 0 | J21: =VLOOKUP($A21,Alimentos!$A:$BA,10,FALSE) -> 0 | K21: =VLOOKUP($A21,Alimentos!$A:$BA,11,FALSE) -> 0 | L21: =VLOOKUP($A21,Alimentos!$A:$BA,12,FALSE) -> 0 | M21: =VLOOKUP($A21,Alimentos!$A:$BA,13,FALSE) -> 0 | N21: =VLOOKUP($A21,Alimentos!$A:$BA,14,FALSE) -> 0 | O21: =VLOOKUP($A21,Alimentos!$A:$BA,15,FALSE) -> 0 | P21: =VLOOKUP($A21,Alimentos!$A:$BA,16,FALSE) -> 0 | Q21: =VLOOKUP($A21,Alimentos!$A:$BA,17,FALSE) -> 0 | R21: =VLOOKUP($A21,Alimentos!$A:$BA,18,FALSE) -> 0 | S21: =VLOOKUP($A21,Alimentos!$A:$BA,19,FALSE) -> 0 | T21: =VLOOKUP($A21,Alimentos!$A:$BA,20,FALSE) -> 0 | U21: =VLOOKUP($A21,Alimentos!$A:$BA,21,FALSE) -> 0 | V21: =VLOOKUP($A21,Alimentos!$A:$BA,22,FALSE) -> 0 | W21: =VLOOKUP($A21,Alimentos!$A:$BA,23,FALSE) -> 0 | X21: =VLOOKUP($A21,Alimentos!$A:$BA,24,FALSE) -> 0 | Y21: =VLOOKUP($A21,Alimentos!$A:$BA,25,FALSE) -> 0 | Z21: =VLOOKUP($A21,Alimentos!$A:$BA,26,FALSE) -> 0 | AA21: =VLOOKUP($A21,Alimentos!$A:$BA,27,FALSE) -> 0 | AB21: =VLOOKUP($A21,Alimentos!$A:$BA,28,FALSE) -> 0 | AC21: =VLOOKUP($A21,Alimentos!$A:$BA,29,FALSE) -> 0 | AD21: =VLOOKUP($A21,Alimentos!$A:$BA,30,FALSE) -> 0 | AE21: =VLOOKUP($A21,Alimentos!$A:$BA,31,FALSE) -> 0 | AF21: =VLOOKUP($A21,Alimentos!$A:$BA,32,FALSE) -> 0 | AG21: =VLOOKUP($A21,Alimentos!$A:$BA,33,FALSE) -> 0 | AH21: =VLOOKUP($A21,Alimentos!$A:$BA,34,FALSE) -> 0 | AI21: =VLOOKUP($A21,Alimentos!$A:$BA,35,FALSE) -> 0 | AJ21: =VLOOKUP($A21,Alimentos!$A:$BA,36,FALSE) -> 0 | AK21: =VLOOKUP($A21,Alimentos!$A:$BA,37,FALSE) -> 0 | AL21: =VLOOKUP($A21,Alimentos!$A:$BA,38,FALSE) -> 0 | AM21: =VLOOKUP($A21,Alimentos!$A:$BA,39,FALSE) -> 0 | AN21: =VLOOKUP($A21,Alimentos!$A:$BA,40,FALSE) -> 0 | AO21: =VLOOKUP($A21,Alimentos!$A:$BA,41,FALSE) -> 0 | AP21: =VLOOKUP($A21,Alimentos!$A:$BA,42,FALSE) -> 0 | AQ21: =VLOOKUP($A21,Alimentos!$A:$BA,43,FALSE) -> 0 | AR21: =VLOOKUP($A21,Alimentos!$A:$BA,44,FALSE) -> 0 | AS21: =VLOOKUP($A21,Alimentos!$A:$BA,45,FALSE) -> 0
A23: Unidades | B23: =B4 -> R$/Kg MN | D23: % MS | E23: kg | F23: kg | G23: kg | H23: kg | I23: kg | J23: kg | K23: kg | L23: kg | M23: kg | N23: kg | O23: Mcal | P23: kg | Q23: kg | R23: kg | S23: kg | T23: kg | U23: kg | V23: kg | W23: kg | X23: kg | Y23: kg | Z23: kg | AA23: kg | AB23: kg | AC23: kg | AD23: kg | AE23: kg | AF23: mg | AG23: mg | AH23: mg | AI23: mg | AJ23: mg | AK23: mg | AL23: mg | AM23: UI | AN23: UI | AO23: UI | AP23: mg | AQ23: mg | AR23: mg | AS23: UFC
A24: Alimento | B24: Custo | D24: MS | E24: MS | F24: PB | G24: PDR | H24: PNDR | I24: FDN | J24: eFDN | K24: FDN>8 | L24: FDN>19 | M24: FDNF | N24: FDA | O24: NEl | P24: NDT | Q24: EE | R24: EE Insat | S24: Cinza | T24: CNF | U24: Amido | V24: Amido DR | W24: Met | X24: Lys | Y24: Ca | Z24: P | AA24: Mg | AB24: K | AC24: S | AD24: Na | AE24: Cl | AF24: Co | AG24: Cu | AH24: Mn | AI24: Zn | AJ24: Se | AK24: I | AL24: Fe | AM24: Vit A | AN24: Vit D3 | AO24: Vit E | AP24: Biotina | AQ24: Monensina | AR24: Cr | AS24: Levedura
A25: =A6 -> x | B25: =C25*B6 -> 0 | D25: =E25/E$43 -> #DIV/0! | E25: =C25*E6 -> 0 | F25: =$E25*F6 -> 0 | G25: =$E25*G6 -> 0 | H25: =$E25*H6 -> 0 | I25: =$E25*I6 -> 0 | J25: =$E25*J6 -> 0 | K25: =IF(AT25="S",((((I6*K6*100)*0.9465)+4.5798)/100)*E25,IF(AT25="F",I6*K6*E25,0)) -> 0 | L25: =IF(AT25="S",((((I6*L6*100)*1.0083)+0.4502)/100)*E25,IF(AT25="F",I6*L6*E25,0)) -> 0 | M25: =$E25*M6 -> 0 | N25: =$E25*N6 -> 0 | O25: =$E25*O6 -> 0 | P25: =$E25*P6 -> 0 | Q25: =$E25*Q6 -> 0 | R25: =$E25*R6 -> 0 | S25: =$E25*S6 -> 0 | T25: =$E25*T6 -> 0 | U25: =$E25*U6 -> 0 | V25: =(V6/(V6+I$56))*U25 -> #DIV/0! | W25: =$E25*W6 -> 0 | X25: =$E25*X6 -> 0 | Y25: =$E25*Y6 -> 0 | Z25: =$E25*Z6 -> 0 | AA25: =$E25*AA6 -> 0 | AB25: =$E25*AB6 -> 0 | AC25: =$E25*AC6 -> 0 | AD25: =$E25*AD6 -> 0 | ... AS25: =$E25*AS6 -> 0 | AT25: =C6 -> 0 | AU25: =($C25/$C$42)*(K6-L6) -> #DIV/0! | AV25: =($C25/$C$42)*L6 -> #DIV/0!
A26: =A7 -> x | B26: =C26*B7 -> 0 | D26: =E26/E$43 -> #DIV/0! | E26: =C26*E7 -> 0 | F26: =$E26*F7 -> 0 | G26: =$E26*G7 -> 0 | H26: =$E26*H7 -> 0 | I26: =$E26*I7 -> 0 | J26: =$E26*J7 -> 0 | K26: =IF(AT26="S",((((I7*K7*100)*0.9465)+4.5798)/100)*E26,IF(AT26="F",I7*K7*E26,0)) -> 0 | L26: =IF(AT26="S",((((I7*L7*100)*1.0083)+0.4502)/100)*E26,IF(AT26="F",I7*L7*E26,0)) -> 0 | M26: =$E26*M7 -> 0 | N26: =$E26*N7 -> 0 | O26: =$E26*O7 -> 0 | P26: =$E26*P7 -> 0 | Q26: =$E26*Q7 -> 0 | R26: =$E26*R7 -> 0 | S26: =$E26*S7 -> 0 | T26: =$E26*T7 -> 0 | U26: =$E26*U7 -> 0 | V26: =(V7/(V7+I$56))*U26 -> #DIV/0! | W26: =$E26*W7 -> 0 | X26: =$E26*X7 -> 0 | Y26: =$E26*Y7 -> 0 | Z26: =$E26*Z7 -> 0 | AA26: =$E26*AA7 -> 0 | AB26: =$E26*AB7 -> 0 | AC26: =$E26*AC7 -> 0 | AD26: =$E26*AD7 -> 0 | ... AS26: =$E26*AS7 -> 0 | AT26: =C7 -> 0 | AU26: =($C26/$C$42)*(K7-L7) -> #DIV/0! | AV26: =($C26/$C$42)*L7 -> #DIV/0!
A27: =A8 -> x | B27: =C27*B8 -> 0 | D27: =E27/E$43 -> #DIV/0! | E27: =C27*E8 -> 0 | F27: =$E27*F8 -> 0 | G27: =$E27*G8 -> 0 | H27: =$E27*H8 -> 0 | I27: =$E27*I8 -> 0 | J27: =$E27*J8 -> 0 | K27: =IF(AT27="S",((((I8*K8*100)*0.9465)+4.5798)/100)*E27,IF(AT27="F",I8*K8*E27,0)) -> 0 | L27: =IF(AT27="S",((((I8*L8*100)*1.0083)+0.4502)/100)*E27,IF(AT27="F",I8*L8*E27,0)) -> 0 | M27: =$E27*M8 -> 0 | N27: =$E27*N8 -> 0 | O27: =$E27*O8 -> 0 | P27: =$E27*P8 -> 0 | Q27: =$E27*Q8 -> 0 | R27: =$E27*R8 -> 0 | S27: =$E27*S8 -> 0 | T27: =$E27*T8 -> 0 | U27: =$E27*U8 -> 0 | V27: =(V8/(V8+I$56))*U27 -> #DIV/0! | W27: =$E27*W8 -> 0 | X27: =$E27*X8 -> 0 | Y27: =$E27*Y8 -> 0 | Z27: =$E27*Z8 -> 0 | AA27: =$E27*AA8 -> 0 | AB27: =$E27*AB8 -> 0 | AC27: =$E27*AC8 -> 0 | AD27: =$E27*AD8 -> 0 | ... AS27: =$E27*AS8 -> 0 | AT27: =C8 -> 0 | AU27: =($C27/$C$42)*(K8-L8) -> #DIV/0! | AV27: =($C27/$C$42)*L8 -> #DIV/0!
A28: =A9 -> x | B28: =C28*B9 -> 0 | D28: =E28/E$43 -> #DIV/0! | E28: =C28*E9 -> 0 | F28: =$E28*F9 -> 0 | G28: =$E28*G9 -> 0 | H28: =$E28*H9 -> 0 | I28: =$E28*I9 -> 0 | J28: =$E28*J9 -> 0 | K28: =IF(AT28="S",((((I9*K9*100)*0.9465)+4.5798)/100)*E28,IF(AT28="F",I9*K9*E28,0)) -> 0 | L28: =IF(AT28="S",((((I9*L9*100)*1.0083)+0.4502)/100)*E28,IF(AT28="F",I9*L9*E28,0)) -> 0 | M28: =$E28*M9 -> 0 | N28: =$E28*N9 -> 0 | O28: =$E28*O9 -> 0 | P28: =$E28*P9 -> 0 | Q28: =$E28*Q9 -> 0 | R28: =$E28*R9 -> 0 | S28: =$E28*S9 -> 0 | T28: =$E28*T9 -> 0 | U28: =$E28*U9 -> 0 | V28: =(V9/(V9+I$56))*U28 -> #DIV/0! | W28: =$E28*W9 -> 0 | X28: =$E28*X9 -> 0 | Y28: =$E28*Y9 -> 0 | Z28: =$E28*Z9 -> 0 | AA28: =$E28*AA9 -> 0 | AB28: =$E28*AB9 -> 0 | AC28: =$E28*AC9 -> 0 | AD28: =$E28*AD9 -> 0 | ... AS28: =$E28*AS9 -> 0 | AT28: =C9 -> 0 | AU28: =($C28/$C$42)*(K9-L9) -> #DIV/0! | AV28: =($C28/$C$42)*L9 -> #DIV/0!
